Workbook

Sheet Performance
F2: Health ( INR Lakhs) | G2: M01'19
F3: GWP | G3: =SuM!C8/100000 -> 32.378274
F4: NEP | G4: =SuM!C26/100000 -> 17.107531
F5: Claims (excluding IBNR)-33% of NEP | G5: =((60760+23748)*0.95)/100000 -> 0.802826 | I5: =G5*100000/G9 -> 743.35741
F6: Claims (including IBNR)-95% of NEP | G6: =((60760+23748)*0.95+154370)/100000 -> 2.346526
F7: Claims service cost(3% of claims) | G7: =3%*G6 -> 0.07039578
F8: No. of Policies | G8: 1592
F9: No. of Claims | G9: 108

Sheet SuM
A1: =C41&":" -> A V GLOBAL CORPORATION PRIVATE LIMITED:
A2: Particulars | C2: Number/₹ | D2: 202602
A3: No of Lives Insured | C3: =SUMIF(Details!B:B,$D$2,Details!AD:AD) -> 11
A4: GWP excl GST | C4: =SUMIF(Details!B:B,$D$2,Details!AE:AE) -> 14562.143
A6: Particulars | B6: Details | C6: Total | E6: 45809 | F6: 45839 | G6: 45870 | H6: 45901 | I6: 45931 | J6: 45962 | K6: 45992 | L6: 46023 | M6: 46054 | O6: Recon
A8: GWP | C8: =Details!AE1 -> 3237827.4 | E8: 3079000.2 | F8: 53716.788 | G8: 25267.084 | H8: 4579.028 | I8: 52998.261 | J8: 3191.5687 | K8: 4512.3233 | L8: 0 | M8: =SUMIF(Details!$B:$B,$D$2,Details!$AE:$AE) -> 14562.143 | O8: =$C8-SUM(E8:M8) -> 0
O9: =$C9-SUM(E9:M9) -> 0
A10: GST: | O10: =$C10-SUM(E10:M10) -> 0
A11: SGST/UGST | C11: =Details!AF1 -> 0 | E11: 0 | F11: 0 | G11: 0 | H11: 0 | I11: 0 | J11: 0 | K11: 0 | L11: 0 | M11: =SUMIF(Details!$B:$B,$D$2,Details!$AF:$AF) -> 0 | O11: =$C11-SUM(E11:M11) -> 0
A12: CGST | C12: =Details!AG1 -> 0 | E12: 0 | F12: 0 | G12: 0 | H12: 0 | I12: 0 | J12: 0 | K12: 0 | L12: 0 | M12: =SUMIF(Details!$B:$B,$D$2,Details!$AG:$AG) -> 0 | O12: =$C12-SUM(E12:M12) -> 0
A13: IGST | C13: =Details!AH1 -> 582808.93 | E13: 554220.03 | F13: 9669.0218 | G13: 4548.0751 | H13: 824.22504 | I13: 9539.687 | J13: 574.48236 | K13: 812.21819 | L13: 0 | M13: =SUMIF(Details!$B:$B,$D$2,Details!$AH:$AH) -> 2621.1858 | O13: =$C13-SUM(E13:M13) -> 0
A14: Total GST | C14: =SUM(C11:C13) -> 582808.93 | E14: 554220.03 | F14: 9669.0218 | G14: 4548.0751 | H14: 824.22504 | I14: 9539.687 | J14: 574.48236 | K14: 812.21819 | L14: 0 | M14: =SUM(M11:M13) -> 2621.1858 | O14: =$C14-SUM(E14:M14) -> 0
O15: =$C15-SUM(E15:M15) -> 0
A16: Reinsurance Premium: | O16: =$C16-SUM(E16:M16) -> 0
A17: Reinsurance Premium - Obligatory | C17: =Details!AI1 -> 129513.09 | E17: 123160.01 | F17: 2148.6715 | G17: 1010.6834 | H17: 183.16112 | I17: 2119.9304 | J17: 127.66275 | K17: 180.49293 | L17: 0 | M17: =SUMIF(Details!$B:$B,$D$2,Details!$AI:$AI) -> 582.48572 | O17: =$C17-SUM(E17:M17) -> 0
A18: Reinsurance Premium - Quota Share | C18: =Details!AJ1 -> 728511.16 | E18: 692775.04 | F18: 12086.277 | G18: 5685.0939 | H18: 1030.2813 | I18: 11924.609 | J18: 718.10295 | K18: 1015.2727 | L18: 0 | M18: =SUMIF(Details!$B:$B,$D$2,Details!$AJ:$AJ) -> 3276.4822 | O18: =$C18-SUM(E18:M18) -> 0
O19: =$C19-SUM(E19:M19) -> 0
A20: Commission on Reinsurance Premium: | O20: =$C20-SUM(E20:M20) -> 0
A21: Reinsurance Commission - Obligatory | C21: =ROUND(C17*10%,0) -> 12951 | E21: 12316 | F21: 215 | G21: 101 | H21: 18 | I21: 212 | J21: 13 | K21: 18 | L21: 0 | M21: =ROUND(M17*10%,0) -> 58 | O21: =$C21-SUM(E21:M21) -> 0
A22: Reinsurance Commission - Quota Share | C22: =ROUND(C18*50%,0) -> 364256 | E22: 346388 | F22: 6043 | G22: 2843 | H22: 515 | I22: 5962 | J22: 359 | K22: 508 | L22: 0 | M22: =ROUND(M18*50%,0) -> 1638 | O22: =$C22-SUM(E22:M22) -> 0
E23: 0 | F23: 0 | G23: 0 | H23: 0 | I23: 0 | J23: 0 | K23: 0 | L23: 0 | M23: =ROUND(M19*10%,0) -> 0 | O23: =$C23-SUM(E23:M23) -> 0
A24: GEP | C24: =Details!AK1 -> 2327555.2 | E24: 177147.95 | F24: 266344.88 | G24: 269822 | H24: 259522.77 | I24: 280278.25 | J24: 266764.71 | K24: 275927.86 | L24: 276569.75 | M24: =$C24-SUM($D24:L24) -> 255177 | O24: =$C24-SUM(E24:M24) -> 0
O25: =$C25-SUM(E25:M25) -> 0
A26: NEP | C26: =Details!AL1 -> 1710753.1 | E26: 130203.75 | F26: 195763.49 | G26: 198319.17 | H26: 190749.24 | I26: 206004.51 | J26: 196072.06 | K26: 202806.97 | L26: 203278.77 | M26: =$C26-SUM($D26:L26) -> 187555.1 | O26: =$C26-SUM(E26:M26) -> 0
O27: =$C27-SUM(E27:M27) -> 0
A28: NURR | C28: =C8-C17-C26-C18 -> 669050.05 | E28: 2132861.4 | F28: -156281.65 | G28: -179747.87 | H28: -187383.65 | I28: -167050.79 | J28: -193726.26 | K28: -199490.42 | L28: -203278.77 | M28: =M8-M17-M26-M18 -> -176851.92 | O28: =$C28-SUM(E28:M28) -> 2.7939677e-09
O29: =$C29-SUM(E29:M29) -> 0
A30: Total No of COI/No of Plan Sold | C30: =Details!X1 -> 245 | E30: 232 | F30: 5 | G30: 2 | H30: 3 | I30: 2 | J30: 0 | K30: -1 | L30: 0 | M30: =SUMIF(Details!$B:$B,$D$2,Details!$X:$X) -> 2 | O30: =$C30-SUM(E30:M30) -> 0
O31: =$C31-SUM(E31:M31) -> 0
A32: Total No of Life Cover | C32: =Details!AD1 -> 688 | E32: 645 | F32: 15 | G32: 5 | H32: 3 | I32: 6 | J32: 1 | K32: 2 | L32: 0 | M32: =SUMIF(Details!$B:$B,$D$2,Details!$AD:$AD) -> 11 | O32: =$C32-SUM(E32:M32) -> 0
O33: =$C33-SUM(E33:M33) -> 0
A34: KMD Insurance Brokerage - 9.75% | O34: =$C34-SUM(E34:M34) -> 0
A35: Commission | C35: =9.75%*C8 -> 315688.17 | E35: 300202.52 | F35: 5237.3868 | G35: 2463.5407 | H35: 446.45523 | I35: 5167.3304 | J35: 311.17794 | K35: 439.95152 | L35: 0 | M35: =$C35-SUM($D35:L35) -> 1419.8089 | O35: =$C35-SUM(E35:M35) -> 0
O36: =$C36-SUM(E36:M36) -> 0
A37: Total SA | C37: =Details!W1 -> 79100000 | E37: 73100000 | F37: 1500000 | G37: 600000 | H37: 1600000 | I37: 2000000 | J37: 0 | K37: -300000 | L37: 0 | M37: =$C37-SUM($D37:L37) -> 600000 | O37: =$C37-SUM(E37:M37) -> 0
O38: =$C38-SUM(E38:M38) -> 0
A39: Master Policy No (Passenger) | C39: =Details!C3 -> GMC021090100AV
A40: Period | C40: : 10-06-2025 to 09-06-2026
A41: Proposer Name | C41: =Details!D3 -> A V GLOBAL CORPORATION PRIVATE LIMITED
A43: Name on Premium Summary | B43: A V GLOBAL-GMC-GMC021090100AV
...

Sheet Details
V1: =ROUND(SUM(V3:V1048576),0) -> 216200000 | W1: =ROUND(SUM(W3:W1048576),0) -> 79100000 | X1: =ROUND(SUM(X3:X1048576),0) -> 245 | Z1: 46081 | AB1: Total | AC1: =ROUND(SUM(AC3:AC1048576),0) -> 3820636 | AD1: =ROUND(SUM(AD3:AD1048576),0) -> 688 | AE1: =SUM(AE3:AE1048576) -> 3237827.4 | AF1: =SUM(AF3:AF1048576) -> 0 | AG1: =SUM(AG3:AG1048576) -> 0 | AH1: =SUM(AH3:AH1048576) -> 582808.93 | AI1: =SUM(AI3:AI1048576) -> 129513.09 | AJ1: =SUM(AJ3:AJ1048576) -> 728511.16 | AK1: =SUM(AK3:AK1048576) -> 2327555.2 | AL1: =SUM(AL3:AL1048576) -> 1710753.1 | AM1: =SUM(AM3:AM1048576) -> 669050.05 | AO1: =ROUND(SUM(AO3:AO1048576),0) -> 3237827
A2: Status | B2: Acct. Month | C2: Master Policy No | D2: Master Policy Holder Name | E2: Master Policy Risk Start Date | F2: Master Policy Risk End Date | G2: Name | H2: Emp ID | I2: DOB | J2: UHID | K2: Policy Risk Start Date | L2: Ri Obligatory | M2: RI Quota | N2: Risk Start Date | O2: Risk End Date | P2: Last Working Day | Q2: Reversal Date | R2: Age | S2: Age Band | T2: Gender | U2: Relationship | V2: Sum Insured | W2: Reporting Sum Insured | X2: No of Policies | Y2: Risk Days | Z2: Base Date | AA2: Used | AB2: State | AC2: Gross Premium | AD2: No of Person Cover Per Day | AE2: GWP | AF2: SGST/UGST | AG2: CGST | AH2: IGST | AI2: Reinsurance Premium -Obligatory | AJ2: Reinsurance Premium -Quota | AK2: GEP | AL2: NEP | AM2: NURR | AN2: Unexpired Premium Date | AO2: Unexpired Premium | AP2: Claim Status
A3: Valid | B3: 202506 | C3: GMC021090100AV | D3: A V GLOBAL CORPORATION PRIVATE LIMITED | E3: 45818 | F3: 46182 | G3: Vijay Mehta | H3: 1001 | I3: 20323 | J3: ACK.F683A520250005.1 | K3: =N3 -> 45818 | L3: =IF(K3>=DATE(2022,4,1),4%,5%) -> 0.04 | M3: 0.225 | N3: 45818 | O3: 46182 | R3: 69 | S3: =VLOOKUP(R3,SA!$B$5:$C$11,2,1) -> 66-70 | T3: Male | U3: Self | V3: 1000000 | W3: =IF(U3="self",V3,0) -> 1000000 | X3: =IF(U3="self",1,0) -> 1 | Y3: =O3-N3+1 -> 365 | Z3: =$Z$1 -> 46081 | AA3: =IF(MIN((Z3-N3)+1,Y3)<0,0,MIN((Z3-N3)+1,Y3)) -> 264 | AB3: Delhi | AC3: =AE3+AF3+AG3+AH3 -> 64504.381 | AD3: 1 | AE3: =IFERROR(INDEX(SA!$C$4:$E$11,MATCH(Details!S3,SA!$C$4:$C$11,0),MATCH(Details!V3,SA!$C$4:$E$4,0)),0)*Y3/(F3-E3+1) -> 54664.73 | AF3: =IF(AB3="Karnataka",AE3*9%,0) -> 0 | AG3: =IF(AB3="Karnataka",AE3*9%,0) -> 0 | AH3: =IF(AF3+AG3>0,0,AE3*18%) -> 9839.6514 | AI3: =AE3*L3 -> 2186.5892 | AJ3: =$AE3*M3 -> 12299.564 | AK3: =(AE3)*AA3/Y3 -> 39538.325 | AL3: =AK3*(1-L3-M3) -> 29060.669 | AM3: =AE3-AI3-AL3-AJ3 -> 11117.907 | AN3: =Z3-366 -> 45715 | AO3: =IF(AND(O3>Z3,N3>AN3),AE3,0) -> 54664.73
A4: Valid | B4: 202506 | C4: GMC021090100AV | D4: A V GLOBAL CORPORATION PRIVATE LIMITED | E4: 45818 | F4: 46182 | G4: Geeta Mehta | H4: 1001 | I4: 22717 | J4: ACK.F683A520250005.2 | K4: =N4 -> 45818 | L4: =IF(K4>=DATE(2022,4,1),4%,5%) -> 0.04 | M4: 0.225 | N4: 45818 | O4: 46182 | R4: 63 | S4: =VLOOKUP(R4,SA!$B$5:$C$11,2,1) -> 56-65 | T4: Female | U4: Spouse | V4: 1000000 | W4: =IF(U4="self",V4,0) -> 0 | X4: =IF(U4="self",1,0) -> 0 | Y4: =O4-N4+1 -> 365 | Z4: =$Z$1 -> 46081 | AA4: =IF(MIN((Z4-N4)+1,Y4)<0,0,MIN((Z4-N4)+1,Y4)) -> 264 | AB4: Delhi | AC4: =AE4+AF4+AG4+AH4 -> 30696.579 | AD4: 1 | AE4: =IFERROR(INDEX(SA!$C$4:$E$11,MATCH(Details!S4,SA!$C$4:$C$11,0),MATCH(Details!V4,SA!$C$4:$E$4,0)),0)*Y4/(F4-E4+1) -> 26014.05 | AF4: =IF(AB4="Karnataka",AE4*9%,0) -> 0 | AG4: =IF(AB4="Karnataka",AE4*9%,0) -> 0 | AH4: =IF(AF4+AG4>0,0,AE4*18%) -> 4682.529 | AI4: =AE4*L4 -> 1040.562 | AJ4: =$AE4*M4 -> 5853.1613 | AK4: =(AE4)*AA4/Y4 -> 18815.642 | AL4: =AK4*(1-L4-M4) -> 13829.497 | AM4: =AE4-AI4-AL4-AJ4 -> 5290.8301 | AN4: =Z4-366 -> 45715 | AO4: =IF(AND(O4>Z4,N4>AN4),AE4,0) -> 26014.05
A5: Valid | B5: 202506 | C5: GMC021090100AV | D5: A V GLOBAL CORPORATION PRIVATE LIMITED | E5: 45818 | F5: 46182 | G5: Ashok Kumar Mehta | H5: 1002 | I5: 19982 | J5: ACK.F683A520250002.1 | K5: =N5 -> 45818 | L5: =IF(K5>=DATE(2022,4,1),4%,5%) -> 0.04 | M5: 0.225 | N5: 45818 | O5: 46182 | R5: 70 | S5: =VLOOKUP(R5,SA!$B$5:$C$11,2,1) -> 66-70 | T5: Male | U5: Self | V5: 1000000 | W5: =IF(U5="self",V5,0) -> 1000000 | X5: =IF(U5="self",1,0) -> 1 | Y5: =O5-N5+1 -> 365 | Z5: =$Z$1 -> 46081 | AA5: =IF(MIN((Z5-N5)+1,Y5)<0,0,MIN((Z5-N5)+1,Y5)) -> 264 | AB5: Delhi | AC5: =AE5+AF5+AG5+AH5 -> 64504.381 | AD5: 1 | AE5: =IFERROR(INDEX(SA!$C$4:$E$11,MATCH(Details!S5,SA!$C$4:$C$11,0),MATCH(Details!V5,SA!$C$4:$E$4,0)),0)*Y5/(F5-E5+1) -> 54664.73 | AF5: =IF(AB5="Karnataka",AE5*9%,0) -> 0 | AG5: =IF(AB5="Karnataka",AE5*9%,0) -> 0 | AH5: =IF(AF5+AG5>0,0,AE5*18%) -> 9839.6514 | AI5: =AE5*L5 -> 2186.5892 | AJ5: =$AE5*M5 -> 12299.564 | AK5: =(AE5)*AA5/Y5 -> 39538.325 | AL5: =AK5*(1-L5-M5) -> 29060.669 | AM5: =AE5-AI5-AL5-AJ5 -> 11117.907 | AN5: =Z5-366 -> 45715 | AO5: =IF(AND(O5>Z5,N5>AN5),AE5,0) -> 54664.73
A6: Valid | B6: 202506 | C6: GMC021090100AV | D6: A V GLOBAL CORPORATION PRIVATE LIMITED | E6: 45818 | F6: 46182 | G6: Ratnesh Kumar Jha | H6: 1004 | I6: 28185 | J6: ACK.F683A520250003.1 | K6: =N6 -> 45818 | L6: =IF(K6>=DATE(2022,4,1),4%,5%) -> 0.04 | M6: 0.225 | N6: 45818 | O6: 46182 | R6: 48 | S6: =VLOOKUP(R6,SA!$B$5:$C$11,2,1) -> 46-55 | T6: Male | U6: Self | V6: 300000 | W6: =IF(U6="self",V6,0) -> 300000 | X6: =IF(U6="self",1,0) -> 1 | Y6: =O6-N6+1 -> 365 | Z6: =$Z$1 -> 46081 | AA6: =IF(MIN((Z6-N6)+1,Y6)<0,0,MIN((Z6-N6)+1,Y6)) -> 264 | AB6: Delhi | AC6: =AE6+AF6+AG6+AH6 -> 9586.9926 | AD6: 1 | AE6: =IFERROR(INDEX(SA!$C$4:$E$11,MATCH(Details!S6,SA!$C$4:$C$11,0),MATCH(Details!V6,SA!$C$4:$E$4,0)),0)*Y6/(F6-E6+1) -> 8124.57 | AF6: =IF(AB6="Karnataka",AE6*9%,0) -> 0 | AG6: =IF(AB6="Karnataka",AE6*9%,0) -> 0 | AH6: =IF(AF6+AG6>0,0,AE6*18%) -> 1462.4226 | AI6: =AE6*L6 -> 324.9828 | AJ6: =$AE6*M6 -> 1828.0283 | AK6: =(AE6)*AA6/Y6 -> 5876.4013 | AL6: =AK6*(1-L6-M6) -> 4319.155 | AM6: =AE6-AI6-AL6-AJ6 -> 1652.404 | AN6: =Z6-366 -> 45715 | AO6: =IF(AND(O6>Z6,N6>AN6),AE6,0) -> 8124.57
A7: Valid | B7: 202506 | C7: GMC021090100AV | D7: A V GLOBAL CORPORATION PRIVATE LIMITED | E7: 45818 | F7: 46182 | G7: Ashwani Kumar Jha | H7: 1004 | I7: 38297 | J7: ACK.F683A520250003.2 | K7: =N7 -> 45818 | L7: =IF(K7>=DATE(2022,4,1),4%,5%) -> 0.04 | M7: 0.225 | N7: 45818 | O7: 46182 | R7: 20 | S7: =VLOOKUP(R7,SA!$B$5:$C$11,2,1) -> 0-35 | T7: Male | U7: Son | V7: 300000 | W7: =IF(U7="self",V7,0) -> 0 | X7: =IF(U7="self",1,0) -> 0 | Y7: =O7-N7+1 -> 365 | Z7: =$Z$1 -> 46081 | AA7: =IF(MIN((Z7-N7)+1,Y7)<0,0,MIN((Z7-N7)+1,Y7)) -> 264 | AB7: Delhi | AC7: =AE7+AF7+AG7+AH7 -> 3874.2114 | AD7: 1 | AE7: =IFERROR(INDEX(SA!$C$4:$E$11,MATCH(Details!S7,SA!$C$4:$C$11,0),MATCH(Details!V7,SA!$C$4:$E$4,0)),0)*Y7/(F7-E7+1) -> 3283.23 | AF7: =IF(AB7="Karnataka",AE7*9%,0) -> 0 | AG7: =IF(AB7="Karnataka",AE7*9%,0) -> 0 | AH7: =IF(AF7+AG7>0,0,AE7*18%) -> 590.9814 | AI7: =AE7*L7 -> 131.3292 | AJ7: =$AE7*M7 -> 738.72675 | AK7: =(AE7)*AA7/Y7 -> 2374.7198 | AL7: =AK7*(1-L7-M7) -> 1745.419 | AM7: =AE7-AI7-AL7-AJ7 -> 667.75501 | AN7: =Z7-366 -> 45715 | AO7: =IF(AND(O7>Z7,N7>AN7),AE7,0) -> 3283.23
A8: Valid | B8: 202506 | C8: GMC021090100AV | D8: A V GLOBAL CORPORATION PRIVATE LIMITED | E8: 45818 | F8: 46182 | G8: Ankit Kumar Jha | H8: 1004 | I8: 39723 | J8: ACK.F683A520250003.3 | K8: =N8 -> 45818 | L8: =IF(K8>=DATE(2022,4,1),4%,5%) -> 0.04 | M8: 0.225 | N8: 45818 | O8: 46182 | R8: 16 | S8: =VLOOKUP(R8,SA!$B$5:$C$11,2,1) -> 0-35 | T8: Male | U8: Son | V8: 300000 | W8: =IF(U8="self",V8,0) -> 0 | X8: =IF(U8="self",1,0) -> 0 | Y8: =O8-N8+1 -> 365 | Z8: =$Z$1 -> 46081 | AA8: =IF(MIN((Z8-N8)+1,Y8)<0,0,MIN((Z8-N8)+1,Y8)) -> 264 | AB8: Delhi | AC8: =AE8+AF8+AG8+AH8 -> 3874.2114 | AD8: 1 | AE8: =IFERROR(INDEX(SA!$C$4:$E$11,MATCH(Details!S8,SA!$C$4:$C$11,0),MATCH(Details!V8,SA!$C$4:$E$4,0)),0)*Y8/(F8-E8+1) -> 3283.23 | AF8: =IF(AB8="Karnataka",AE8*9%,0) -> 0 | AG8: =IF(AB8="Karnataka",AE8*9%,0) -> 0 | AH8: =IF(AF8+AG8>0,0,AE8*18%) -> 590.9814 | AI8: =AE8*L8 -> 131.3292 | AJ8: =$AE8*M8 -> 738.72675 | AK8: =(AE8)*AA8/Y8 -> 2374.7198 | AL8: =AK8*(1-L8-M8) -> 1745.419 | AM8: =AE8-AI8-AL8-AJ8 -> 667.75501 | AN8: =Z8-366 -> 45715 | AO8: =IF(AND(O8>Z8,N8>AN8),AE8,0) -> 3283.23
A9: Valid | B9: 202506 | C9: GMC021090100AV | D9: A V GLOBAL CORPORATION PRIVATE LIMITED | E9: 45818 | F9: 46182 | G9: Gudiya Jha | H9: 1004 | I9: 31215 | J9: ACK.F683A520250003.4 | K9: =N9 -> 45818 | L9: =IF(K9>=DATE(2022,4,1),4%,5%) -> 0.04 | M9: 0.225 | N9: 45818 | O9: 46182 | R9: 39 | S9: =VLOOKUP(R9,SA!$B$5:$C$11,2,1) -> 36-45 | T9: Female | U9: Spouse | V9: 300000 | W9: =IF(U9="self",V9,0) -> 0 | X9: =IF(U9="self",1,0) -> 0 | Y9: =O9-N9+1 -> 365 | Z9: =$Z$1 -> 46081 | AA9: =IF(MIN((Z9-N9)+1,Y9)<0,0,MIN((Z9-N9)+1,Y9)) -> 264 | AB9: Delhi | AC9: =AE9+AF9+AG9+AH9 -> 5017.3246 | AD9: 1 | AE9: =IFERROR(INDEX(SA!$C$4:$E$11,MATCH(Details!S9,SA!$C$4:$C$11,0),MATCH(Details!V9,SA!$C$4:$E$4,0)),0)*Y9/(F9-E9+1) -> 4251.97 | AF9: =IF(AB9="Karnataka",AE9*9%,0) -> 0 | AG9: =IF(AB9="Karnataka",AE9*9%,0) -> 0 | AH9: =IF(AF9+AG9>0,0,AE9*18%) -> 765.3546 | AI9: =AE9*L9 -> 170.0788 | AJ9: =$AE9*M9 -> 956.69325 | AK9: =(AE9)*AA9/Y9 -> 3075.3975 | AL9: =AK9*(1-L9-M9) -> 2260.4171 | AM9: =AE9-AI9-AL9-AJ9 -> 864.7808 | AN9: =Z9-366 -> 45715 | AO9: =IF(AND(O9>Z9,N9>AN9),AE9,0) -> 4251.97
A10: Valid | B10: 202506 | C10: GMC021090100AV | D10: A V GLOBAL CORPORATION PRIVATE LIMITED | E10: 45818 | F10: 46182 | G10: Ritesh Ranjan | H10: 1005 | I10: 27820 | J10: ACK.F683A520250006.1 | K10: =N10 -> 45818 | L10: =IF(K10>=DATE(2022,4,1),4%,5%) -> 0.04 | M10: 0.225 | N10: 45818 | O10: 46182 | R10: 49 | S10: =VLOOKUP(R10,SA!$B$5:$C$11,2,1) -> 46-55 | T10: Male | U10: Self | V10: 300000 | W10: =IF(U10="self",V10,0) -> 300000 | X10: =IF(U10="self",1,0) -> 1 | Y10: =O10-N10+1 -> 365 | Z10: =$Z$1 -> 46081 | AA10: =IF(MIN((Z10-N10)+1,Y10)<0,0,MIN((Z10-N10)+1,Y10)) -> 264 | AB10: Delhi | AC10: =AE10+AF10+AG10+AH10 -> 9586.9926 | AD10: 1 | AE10: =IFERROR(INDEX(SA!$C$4:$E$11,MATCH(Details!S10,SA!$C$4:$C$11,0),MATCH(Details!V10,SA!$C$4:$E$4,0)),0)*Y10/(F10-E10+1) -> 8124.57 | AF10: =IF(AB10="Karnataka",AE10*9%,0) -> 0 | AG10: =IF(AB10="Karnataka",AE10*9%,0) -> 0 | AH10: =IF(AF10+AG10>0,0,AE10*18%) -> 1462.4226 | AI10: =AE10*L10 -> 324.9828 | AJ10: =$AE10*M10 -> 1828.0283 | AK10: =(AE10)*AA10/Y10 -> 5876.4013 | AL10: =AK10*(1-L10-M10) -> 4319.155 | AM10: =AE10-AI10-AL10-AJ10 -> 1652.404 | AN10: =Z10-366 -> 45715 | AO10: =IF(AND(O10>Z10,N10>AN10),AE10,0) -> 8124.57
A11: Valid | B11: 202506 | C11: GMC021090100AV | D11: A V GLOBAL CORPORATION PRIVATE LIMITED | E11: 45818 | F11: 46182 | G11: Neetu Singh | H11: 1005 | I11: 30722 | J11: ACK.F683A520250006.2 | K11: =N11 -> 45818 | L11: =IF(K11>=DATE(2022,4,1),4%,5%) -> 0.04 | M11: 0.225 | N11: 45818 | O11: 46182 | R11: 41 | S11: =VLOOKUP(R11,SA!$B$5:$C$11,2,1) -> 36-45 | T11: Female | U11: Spouse | V11: 300000 | W11: =IF(U11="self",V11,0) -> 0 | X11: =IF(U11="self",1,0) -> 0 | Y11: =O11-N11+1 -> 365 | Z11: =$Z$1 -> 46081 | AA11: =IF(MIN((Z11-N11)+1,Y11)<0,0,MIN((Z11-N11)+1,Y11)) -> 264 | AB11: Delhi | AC11: =AE11+AF11+AG11+AH11 -> 5017.3246 | AD11: 1 | AE11: =IFERROR(INDEX(SA!$C$4:$E$11,MATCH(Details!S11,SA!$C$4:$C$11,0),MATCH(Details!V11,SA!$C$4:$E$4,0)),0)*Y11/(F11-E11+1) -> 4251.97 | AF11: =IF(AB11="Karnataka",AE11*9%,0) -> 0 | AG11: =IF(AB11="Karnataka",AE11*9%,0) -> 0 | AH11: =IF(AF11+AG11>0,0,AE11*18%) -> 765.3546 | AI11: =AE11*L11 -> 170.0788 | AJ11: =$AE11*M11 -> 956.69325 | AK11: =(AE11)*AA11/Y11 -> 3075.3975 | AL11: =AK11*(1-L11-M11) -> 2260.4171 | AM11: =AE11-AI11-AL11-AJ11 -> 864.7808 | AN11: =Z11-366 -> 45715 | AO11: =IF(AND(O11>Z11,N11>AN11),AE11,0) -> 4251.97
A12: Valid | B12: 202506 | C12: GMC021090100AV | D12: A V GLOBAL CORPORATION PRIVATE LIMITED | E12: 45818 | F12: 46182 | G12: Vanshika Singh | H12: 1005 | I12: 38757 | J12: ACK.F683A520250006.3 | K12: =N12 -> 45818 | L12: =IF(K12>=DATE(2022,4,1),4%,5%) -> 0.04 | M12: 0.225 | N12: 45818 | O12: 46182 | R12: 19 | S12: =VLOOKUP(R12,SA!$B$5:$C$11,2,1) -> 0-35 | T12: Female | U12: Daughter | V12: 300000 | W12: =IF(U12="self",V12,0) -> 0 | X12: =IF(U12="self",1,0) -> 0 | Y12: =O12-N12+1 -> 365 | Z12: =$Z$1 -> 46081 | AA12: =IF(MIN((Z12-N12)+1,Y12)<0,0,MIN((Z12-N12)+1,Y12)) -> 264 | AB12: Delhi | AC12: =AE12+AF12+AG12+AH12 -> 3874.2114 | AD12: 1 | AE12: =IFERROR(INDEX(SA!$C$4:$E$11,MATCH(Details!S12,SA!$C$4:$C$11,0),MATCH(Details!V12,SA!$C$4:$E$4,0)),0)*Y12/(F12-E12+1) -> 3283.23 | AF12: =IF(AB12="Karnataka",AE12*9%,0) -> 0 | AG12: =IF(AB12="Karnataka",AE12*9%,0) -> 0 | AH12: =IF(AF12+AG12>0,0,AE12*18%) -> 590.9814 | AI12: =AE12*L12 -> 131.3292 | AJ12: =$AE12*M12 -> 738.72675 | AK12: =(AE12)*AA12/Y12 -> 2374.7198 | AL12: =AK12*(1-L12-M12) -> 1745.419 | AM12: =AE12-AI12-AL12-AJ12 -> 667.75501 | AN12: =Z12-366 -> 45715 | AO12: =IF(AND(O12>Z12,N12>AN12),AE12,0) -> 3283.23
A13: Valid | B13: 202506 | C13: GMC021090100AV | D13: A V GLOBAL CORPORATION PRIVATE LIMITED | E13: 45818 | F13: 46182 | G13: Vaibhav Singh | H13: 1005 | I13: 39150 | J13: ACK.F683A520250006.4 | K13: =N13 -> 45818 | L13: =IF(K13>=DATE(2022,4,1),4%,5%) -> 0.04 | M13: 0.225 | N13: 45818 | O13: 46182 | R13: 18 | S13: =VLOOKUP(R13,SA!$B$5:$C$11,2,1) -> 0-35 | T13: Male | U13: Son | V13: 300000 | W13: =IF(U13="self",V13,0) -> 0 | X13: =IF(U13="self",1,0) -> 0 | Y13: =O13-N13+1 -> 365 | Z13: =$Z$1 -> 46081 | AA13: =IF(MIN((Z13-N13)+1,Y13)<0,0,MIN((Z13-N13)+1,Y13)) -> 264 | AB13: Delhi | AC13: =AE13+AF13+AG13+AH13 -> 3874.2114 | AD13: 1 | AE13: =IFERROR(INDEX(SA!$C$4:$E$11,MATCH(Details!S13,SA!$C$4:$C$11,0),MATCH(Details!V13,SA!$C$4:$E$4,0)),0)*Y13/(F13-E13+1) -> 3283.23 | AF13: =IF(AB13="Karnataka",AE13*9%,0) -> 0 | AG13: =IF(AB13="Karnataka",AE13*9%,0) -> 0 | AH13: =IF(AF13+AG13>0,0,AE13*18%) -> 590.9814 | AI13: =AE13*L13 -> 131.3292 | AJ13: =$AE13*M13 -> 738.72675 | AK13: =(AE13)*AA13/Y13 -> 2374.7198 | AL13: =AK13*(1-L13-M13) -> 1745.419 | AM13: =AE13-AI13-AL13-AJ13 -> 667.75501 | AN13: =Z13-366 -> 45715 | AO13: =IF(AND(O13>Z13,N13>AN13),AE13,0) -> 3283.23
A14: Valid | B14: 202506 | C14: GMC021090100AV | D14: A V GLOBAL CORPORATION PRIVATE LIMITED | E14: 45818 | F14: 46182 | G14: Mini Surendran | H14: 1006 | I14: 25363 | J14: ACK.F683A520250004.1 | K14: =N14 -> 45818 | L14: =IF(K14>=DATE(2022,4,1),4%,5%) -> 0.04 | M14: 0.225 | N14: 45818 | O14: 46182 | R14: 56 | S14: =VLOOKUP(R14,SA!$B$5:$C$11,2,1) -> 56-65 | T14: Female | U14: Self | V14: 300000 | W14: =IF(U14="self",V14,0) -> 300000 | X14: =IF(U14="self",1,0) -> 1 | Y14: =O14-N14+1 -> 365 | Z14: =$Z$1 -> 46081 | AA14: =IF(MIN((Z14-N14)+1,Y14)<0,0,MIN((Z14-N14)+1,Y14)) -> 264 | AB14: Delhi | AC14: =AE14+AF14+AG14+AH14 -> 16811.448 | AD14: 1 | AE14: =IFERROR(INDEX(SA!$C$4:$E$11,MATCH(Details!S14,SA!$C$4:$C$11,0),MATCH(Details!V14,SA!$C$4:$E$4,0)),0)*Y14/(F14-E14+1) -> 14246.99 | AF14: =IF(AB14="Karnataka",AE14*9%,0) -> 0 | AG14: =IF(AB14="Karnataka",AE14*9%,0) -> 0 | AH14: =IF(AF14+AG14>0,0,AE14*18%) -> 2564.4582 | AI14: =AE14*L14 -> 569.8796 | AJ14: =$AE14*M14 -> 3205.5727 | AK14: =(AE14)*AA14/Y14 -> 10304.672 | AL14: =AK14*(1-L14-M14) -> 7573.9341 | AM14: =AE14-AI14-AL14-AJ14 -> 2897.6036 | AN14: =Z14-366 -> 45715 | AO14: =IF(AND(O14>Z14,N14>AN14),AE14,0) -> 14246.99
... A582: Valid | B582: 202506 | C582: GMC021090100AV | D582: A V GLOBAL CORPORATION PRIVATE LIMITED | E582: 45818 | F582: 46182 | G582: S Shazia | H582: 4019 | I582: 44815 | J582: ACK.F683A520250228.4 | K582: =N582 -> 45818 | L582: =IF(K582>=DATE(2022,4,1),4%,5%) -> 0.04 | M582: 0.225 | N582: 45818 | O582: 46182 | R582: 2 | S582: =VLOOKUP(R582,SA!$B$5:$C$11,2,1) -> 0-35 | T582: Female | U582: Daughter | V582: 300000 | W582: =IF(U582="self",V582,0) -> 0 | X582: =IF(U582="self",1,0) -> 0 | Y582: =O582-N582+1 -> 365 | Z582: =$Z$1 -> 46081 | AA582: =IF(MIN((Z582-N582)+1,Y582)<0,0,MIN((Z582-N582)+1,Y582)) -> 264 | AB582: Delhi | AC582: =AE582+AF582+AG582+AH582 -> 3874.2114 | AD582: 1 | AE582: =IFERROR(INDEX(SA!$C$4:$E$11,MATCH(Details!S582,SA!$C$4:$C$11,0),MATCH(Details!V582,SA!$C$4:$E$4,0)),0)*Y582/(F582-E582+1) -> 3283.23 | AF582: =IF(AB582="Karnataka",AE582*9%,0) -> 0 | AG582: =IF(AB582="Karnataka",AE582*9%,0) -> 0 | AH582: =IF(AF582+AG582>0,0,AE582*18%) -> 590.9814 | AI582: =AE582*L582 -> 131.3292 | AJ582: =$AE582*M582 -> 738.72675 | AK582: =(AE582)*AA582/Y582 -> 2374.7198 | AL582: =AK582*(1-L582-M582) -> 1745.419 | AM582: =AE582-AI582-AL582-AJ582 -> 667.75501 | AN582: =Z582-366 -> 45715 | AO582: =IF(AND(O582>Z582,N582>AN582),AE582,0) -> 3283.23
A583: Valid | B583: 202506 | C583: GMC021090100AV | D583: A V GLOBAL CORPORATION PRIVATE LIMITED | E583: 45818 | F583: 46182 | G583: Anand Kumar Jha | H583: AVGCT1 | I583: 34395 | J583: ACK.F683A520250226.1 | K583: =N583 -> 45818 | L583: =IF(K583>=DATE(2022,4,1),4%,5%) -> 0.04 | M583: 0.225 | N583: 45818 | O583: 46182 | R583: 31 | S583: =VLOOKUP(R583,SA!$B$5:$C$11,2,1) -> 0-35 | T583: Male | U583: Self | V583: 300000 | W583: =IF(U583="self",V583,0) -> 300000 | X583: =IF(U583="self",1,0) -> 1 | Y583: =O583-N583+1 -> 365 | Z583: =$Z$1 -> 46081 | AA583: =IF(MIN((Z583-N583)+1,Y583)<0,0,MIN((Z583-N583)+1,Y583)) -> 264 | AB583: Delhi | AC583: =AE583+AF583+AG583+AH583 -> 3874.2114 | AD583: 1 | AE583: =IFERROR(INDEX(SA!$C$4:$E$11,MATCH(Details!S583,SA!$C$4:$C$11,0),MATCH(Details!V583,SA!$C$4:$E$4,0)),0)*Y583/(F583-E583+1) -> 3283.23 | AF583: =IF(AB583="Karnataka",AE583*9%,0) -> 0 | AG583: =IF(AB583="Karnataka",AE583*9%,0) -> 0 | AH583: =IF(AF583+AG583>0,0,AE583*18%) -> 590.9814 | AI583: =AE583*L583 -> 131.3292 | AJ583: =$AE583*M583 -> 738.72675 | AK583: =(AE583)*AA583/Y583 -> 2374.7198 | AL583: =AK583*(1-L583-M583) -> 1745.419 | AM583: =AE583-AI583-AL583-AJ583 -> 667.75501 | AN583: =Z583-366 -> 45715 | AO583: =IF(AND(O583>Z583,N583>AN583),AE583,0) -> 3283.23
A584: Valid | B584: 202506 | C584: GMC021090100AV | D584: A V GLOBAL CORPORATION PRIVATE LIMITED | E584: 45818 | F584: 46182 | G584: Priyadarshani Kumari | H584: AVGCT1 | I584: 35124 | J584: ACK.F683A520250226.2 | K584: =N584 -> 45818 | L584: =IF(K584>=DATE(2022,4,1),4%,5%) -> 0.04 | M584: 0.225 | N584: 45818 | O584: 46182 | R584: 29 | S584: =VLOOKUP(R584,SA!$B$5:$C$11,2,1) -> 0-35 | T584: Female | U584: Spouse | V584: 300000 | W584: =IF(U584="self",V584,0) -> 0 | X584: =IF(U584="self",1,0) -> 0 | Y584: =O584-N584+1 -> 365 | Z584: =$Z$1 -> 46081 | AA584: =IF(MIN((Z584-N584)+1,Y584)<0,0,MIN((Z584-N584)+1,Y584)) -> 264 | AB584: Delhi | AC584: =AE584+AF584+AG584+AH584 -> 3874.2114 | AD584: 1 | AE584: =IFERROR(INDEX(SA!$C$4:$E$11,MATCH(Details!S584,SA!$C$4:$C$11,0),MATCH(Details!V584,SA!$C$4:$E$4,0)),0)*Y584/(F584-E584+1) -> 3283.23 | AF584: =IF(AB584="Karnataka",AE584*9%,0) -> 0 | AG584: =IF(AB584="Karnataka",AE584*9%,0) -> 0 | AH584: =IF(AF584+AG584>0,0,AE584*18%) -> 590.9814 | AI584: =AE584*L584 -> 131.3292 | AJ584: =$AE584*M584 -> 738.72675 | AK584: =(AE584)*AA584/Y584 -> 2374.7198 | AL584: =AK584*(1-L584-M584) -> 1745.419 | AM584: =AE584-AI584-AL584-AJ584 -> 667.75501 | AN584: =Z584-366 -> 45715 | AO584: =IF(AND(O584>Z584,N584>AN584),AE584,0) -> 3283.23
A585: Valid | B585: 202506 | C585: GMC021090100AV | D585: A V GLOBAL CORPORATION PRIVATE LIMITED | E585: 45818 | F585: 46182 | G585: Sanvi Jha | H585: AVGCT1 | I585: 44581 | J585: ACK.F683A520250226.3 | K585: =N585 -> 45818 | L585: =IF(K585>=DATE(2022,4,1),4%,5%) -> 0.04 | M585: 0.225 | N585: 45818 | O585: 46182 | R585: 3 | S585: =VLOOKUP(R585,SA!$B$5:$C$11,2,1) -> 0-35 | T585: Female | U585: Daughter | V585: 300000 | W585: =IF(U585="self",V585,0) -> 0 | X585: =IF(U585="self",1,0) -> 0 | Y585: =O585-N585+1 -> 365 | Z585: =$Z$1 -> 46081 | AA585: =IF(MIN((Z585-N585)+1,Y585)<0,0,MIN((Z585-N585)+1,Y585)) -> 264 | AB585: Delhi | AC585: =AE585+AF585+AG585+AH585 -> 3874.2114 | AD585: 1 | AE585: =IFERROR(INDEX(SA!$C$4:$E$11,MATCH(Details!S585,SA!$C$4:$C$11,0),MATCH(Details!V585,SA!$C$4:$E$4,0)),0)*Y585/(F585-E585+1) -> 3283.23 | AF585: =IF(AB585="Karnataka",AE585*9%,0) -> 0 | AG585: =IF(AB585="Karnataka",AE585*9%,0) -> 0 | AH585: =IF(AF585+AG585>0,0,AE585*18%) -> 590.9814 | AI585: =AE585*L585 -> 131.3292 | AJ585: =$AE585*M585 -> 738.72675 | AK585: =(AE585)*AA585/Y585 -> 2374.7198 | AL585: =AK585*(1-L585-M585) -> 1745.419 | AM585: =AE585-AI585-AL585-AJ585 -> 667.75501 | AN585: =Z585-366 -> 45715 | AO585: =IF(AND(O585>Z585,N585>AN585),AE585,0) -> 3283.23
A586: Valid | B586: 202506 | C586: GMC021090100AV | D586: A V GLOBAL CORPORATION PRIVATE LIMITED | E586: 45818 | F586: 46182 | G586: Rajiv Kumar | H586: AVGCT2 | I586: 29952 | J586: ACK.F683A520250229.1 | K586: =N586 -> 45818 | L586: =IF(K586>=DATE(2022,4,1),4%,5%) -> 0.04 | M586: 0.225 | N586: 45818 | O586: 46182 | R586: 43 | S586: =VLOOKUP(R586,SA!$B$5:$C$11,2,1) -> 36-45 | T586: Male | U586: Self | V586: 300000 | W586: =IF(U586="self",V586,0) -> 300000 | X586: =IF(U586="self",1,0) -> 1 | Y586: =O586-N586+1 -> 365 | Z586: =$Z$1 -> 46081 | AA586: =IF(MIN((Z586-N586)+1,Y586)<0,0,MIN((Z586-N586)+1,Y586)) -> 264 | AB586: Delhi | AC586: =AE586+AF586+AG586+AH586 -> 5017.3246 | AD586: 1 | AE586: =IFERROR(INDEX(SA!$C$4:$E$11,MATCH(Details!S586,SA!$C$4:$C$11,0),MATCH(Details!V586,SA!$C$4:$E$4,0)),0)*Y586/(F586-E586+1) -> 4251.97 | AF586: =IF(AB586="Karnataka",AE586*9%,0) -> 0 | AG586: =IF(AB586="Karnataka",AE586*9%,0) -> 0 | AH586: =IF(AF586+AG586>0,0,AE586*18%) -> 765.3546 | AI586: =AE586*L586 -> 170.0788 | AJ586: =$AE586*M586 -> 956.69325 | AK586: =(AE586)*AA586/Y586 -> 3075.3975 | AL586: =AK586*(1-L586-M586) -> 2260.4171 | AM586: =AE586-AI586-AL586-AJ586 -> 864.7808 | AN586: =Z586-366 -> 45715 | AO586: =IF(AND(O586>Z586,N586>AN586),AE586,0) -> 4251.97
A587: Valid | B587: 202506 | C587: GMC021090100AV | D587: A V GLOBAL CORPORATION PRIVATE LIMITED | E587: 45818 | F587: 46182 | G587: Malti | H587: AVGCT2 | I587: 28950 | J587: ACK.F683A520250229.2 | K587: =N587 -> 45818 | L587: =IF(K587>=DATE(2022,4,1),4%,5%) -> 0.04 | M587: 0.225 | N587: 45818 | O587: 46182 | R587: 46 | S587: =VLOOKUP(R587,SA!$B$5:$C$11,2,1) -> 46-55 | T587: Female | U587: Spouse | V587: 300000 | W587: =IF(U587="self",V587,0) -> 0 | X587: =IF(U587="self",1,0) -> 0 | Y587: =O587-N587+1 -> 365 | Z587: =$Z$1 -> 46081 | AA587: =IF(MIN((Z587-N587)+1,Y587)<0,0,MIN((Z587-N587)+1,Y587)) -> 264 | AB587: Delhi | AC587: =AE587+AF587+AG587+AH587 -> 9586.9926 | AD587: 1 | AE587: =IFERROR(INDEX(SA!$C$4:$E$11,MATCH(Details!S587,SA!$C$4:$C$11,0),MATCH(Details!V587,SA!$C$4:$E$4,0)),0)*Y587/(F587-E587+1) -> 8124.57 | AF587: =IF(AB587="Karnataka",AE587*9%,0) -> 0 | AG587: =IF(AB587="Karnataka",AE587*9%,0) -> 0 | AH587: =IF(AF587+AG587>0,0,AE587*18%) -> 1462.4226 | AI587: =AE587*L587 -> 324.9828 | AJ587: =$AE587*M587 -> 1828.0283 | AK587: =(AE587)*AA587/Y587 -> 5876.4013 | AL587: =AK587*(1-L587-M587) -> 4319.155 | AM587: =AE587-AI587-AL587-AJ587 -> 1652.404 | AN587: =Z587-366 -> 45715 | AO587: =IF(AND(O587>Z587,N587>AN587),AE587,0) -> 8124.57
A588: Valid | B588: 202506 | C588: GMC021090100AV | D588: A V GLOBAL CORPORATION PRIVATE LIMITED | E588: 45818 | F588: 46182 | G588: Philip | H588: AVGCT2 | I588: 36797 | J588: ACK.F683A520250229.3 | K588: =N588 -> 45818 | L588: =IF(K588>=DATE(2022,4,1),4%,5%) -> 0.04 | M588: 0.225 | N588: 45818 | O588: 46182 | R588: 24 | S588: =VLOOKUP(R588,SA!$B$5:$C$11,2,1) -> 0-35 | T588: Male | U588: Son | V588: 300000 | W588: =IF(U588="self",V588,0) -> 0 | X588: =IF(U588="self",1,0) -> 0 | Y588: =O588-N588+1 -> 365 | Z588: =$Z$1 -> 46081 | AA588: =IF(MIN((Z588-N588)+1,Y588)<0,0,MIN((Z588-N588)+1,Y588)) -> 264 | AB588: Delhi | AC588: =AE588+AF588+AG588+AH588 -> 3874.2114 | AD588: 1 | AE588: =IFERROR(INDEX(SA!$C$4:$E$11,MATCH(Details!S588,SA!$C$4:$C$11,0),MATCH(Details!V588,SA!$C$4:$E$4,0)),0)*Y588/(F588-E588+1) -> 3283.23 | AF588: =IF(AB588="Karnataka",AE588*9%,0) -> 0 | AG588: =IF(AB588="Karnataka",AE588*9%,0) -> 0 | AH588: =IF(AF588+AG588>0,0,AE588*18%) -> 590.9814 | AI588: =AE588*L588 -> 131.3292 | AJ588: =$AE588*M588 -> 738.72675 | AK588: =(AE588)*AA588/Y588 -> 2374.7198 | AL588: =AK588*(1-L588-M588) -> 1745.419 | AM588: =AE588-AI588-AL588-AJ588 -> 667.75501 | AN588: =Z588-366 -> 45715 | AO588: =IF(AND(O588>Z588,N588>AN588),AE588,0) -> 3283.23
A589: Valid | B589: 202506 | C589: GMC021090100AV | D589: A V GLOBAL CORPORATION PRIVATE LIMITED | E589: 45818 | F589: 46182 | G589: Joy | H589: AVGCT2 | I589: 39861 | J589: ACK.F683A520250229.4 | K589: =N589 -> 45818 | L589: =IF(K589>=DATE(2022,4,1),4%,5%) -> 0.04 | M589: 0.225 | N589: 45818 | O589: 46182 | R589: 16 | S589: =VLOOKUP(R589,SA!$B$5:$C$11,2,1) -> 0-35 | T589: Male | U589: Son | V589: 300000 | W589: =IF(U589="self",V589,0) -> 0 | X589: =IF(U589="self",1,0) -> 0 | Y589: =O589-N589+1 -> 365 | Z589: =$Z$1 -> 46081 | AA589: =IF(MIN((Z589-N589)+1,Y589)<0,0,MIN((Z589-N589)+1,Y589)) -> 264 | AB589: Delhi | AC589: =AE589+AF589+AG589+AH589 -> 3874.2114 | AD589: 1 | AE589: =IFERROR(INDEX(SA!$C$4:$E$11,MATCH(Details!S589,SA!$C$4:$C$11,0),MATCH(Details!V589,SA!$C$4:$E$4,0)),0)*Y589/(F589-E589+1) -> 3283.23 | AF589: =IF(AB589="Karnataka",AE589*9%,0) -> 0 | AG589: =IF(AB589="Karnataka",AE589*9%,0) -> 0 | AH589: =IF(AF589+AG589>0,0,AE589*18%) -> 590.9814 | AI589: =AE589*L589 -> 131.3292 | AJ589: =$AE589*M589 -> 738.72675 | AK589: =(AE589)*AA589/Y589 -> 2374.7198 | AL589: =AK589*(1-L589-M589) -> 1745.419 | AM589: =AE589-AI589-AL589-AJ589 -> 667.75501 | AN589: =Z589-366 -> 45715 | AO589: =IF(AND(O589>Z589,N589>AN589),AE589,0) -> 3283.23
A590: Valid | B590: 202506 | C590: GMC021090100AV | D590: A V GLOBAL CORPORATION PRIVATE LIMITED | E590: 45818 | F590: 46182 | G590: Poonam | H590: AVGCT3 | I590: 34053 | J590: ACK.F683A520250227.1 | K590: =N590 -> 45818 | L590: =IF(K590>=DATE(2022,4,1),4%,5%) -> 0.04 | M590: 0.225 | N590: 45818 | O590: 46182 | R590: 32 | S590: =VLOOKUP(R590,SA!$B$5:$C$11,2,1) -> 0-35 | T590: Female | U590: Self | V590: 300000 | W590: =IF(U590="self",V590,0) -> 300000 | X590: =IF(U590="self",1,0) -> 1 | Y590: =O590-N590+1 -> 365 | Z590: =$Z$1 -> 46081 | AA590: =IF(MIN((Z590-N590)+1,Y590)<0,0,MIN((Z590-N590)+1,Y590)) -> 264 | AB590: Delhi | AC590: =AE590+AF590+AG590+AH590 -> 3874.2114 | AD590: 1 | AE590: =IFERROR(INDEX(SA!$C$4:$E$11,MATCH(Details!S590,SA!$C$4:$C$11,0),MATCH(Details!V590,SA!$C$4:$E$4,0)),0)*Y590/(F590-E590+1) -> 3283.23 | AF590: =IF(AB590="Karnataka",AE590*9%,0) -> 0 | AG590: =IF(AB590="Karnataka",AE590*9%,0) -> 0 | AH590: =IF(AF590+AG590>0,0,AE590*18%) -> 590.9814 | AI590: =AE590*L590 -> 131.3292 | AJ590: =$AE590*M590 -> 738.72675 | AK590: =(AE590)*AA590/Y590 -> 2374.7198 | AL590: =AK590*(1-L590-M590) -> 1745.419 | AM590: =AE590-AI590-AL590-AJ590 -> 667.75501 | AN590: =Z590-366 -> 45715 | AO590: =IF(AND(O590>Z590,N590>AN590),AE590,0) -> 3283.23
A591: Valid | B591: 202506 | C591: GMC021090100AV | D591: A V GLOBAL CORPORATION PRIVATE LIMITED | E591: 45818 | F591: 46182 | G591: Mukesh | H591: AVGCT4 | I591: 34302 | J591: ACK.F683A520250230.1 | K591: =N591 -> 45818 | L591: =IF(K591>=DATE(2022,4,1),4%,5%) -> 0.04 | M591: 0.225 | N591: 45818 | O591: 46182 | R591: 31 | S591: =VLOOKUP(R591,SA!$B$5:$C$11,2,1) -> 0-35 | T591: Male | U591: Self | V591: 300000 | W591: =IF(U591="self",V591,0) -> 300000 | X591: =IF(U591="self",1,0) -> 1 | Y591: =O591-N591+1 -> 365 | Z591: =$Z$1 -> 46081 | AA591: =IF(MIN((Z591-N591)+1,Y591)<0,0,MIN((Z591-N591)+1,Y591)) -> 264 | AB591: Delhi | AC591: =AE591+AF591+AG591+AH591 -> 3874.2114 | AD591: 1 | AE591: =IFERROR(INDEX(SA!$C$4:$E$11,MATCH(Details!S591,SA!$C$4:$C$11,0),MATCH(Details!V591,SA!$C$4:$E$4,0)),0)*Y591/(F591-E591+1) -> 3283.23 | AF591: =IF(AB591="Karnataka",AE591*9%,0) -> 0 | AG591: =IF(AB591="Karnataka",AE591*9%,0) -> 0 | AH591: =IF(AF591+AG591>0,0,AE591*18%) -> 590.9814 | AI591: =AE591*L591 -> 131.3292 | AJ591: =$AE591*M591 -> 738.72675 | AK591: =(AE591)*AA591/Y591 -> 2374.7198 | AL591: =AK591*(1-L591-M591) -> 1745.419 | AM591: =AE591-AI591-AL591-AJ591 -> 667.75501 | AN591: =Z591-366 -> 45715 | AO591: =IF(AND(O591>Z591,N591>AN591),AE591,0) -> 3283.23
A592: Valid | B592: 202506 | C592: GMC021090100AV | D592: A V GLOBAL CORPORATION PRIVATE LIMITED | E592: 45818 | F592: 46182 | G592: Kanchan | H592: AVGCT4 | I592: 33240 | J592: ACK.F683A520250230.2 | K592: =N592 -> 45818 | L592: =IF(K592>=DATE(2022,4,1),4%,5%) -> 0.04 | M592: 0.225 | N592: 45818 | O592: 46182 | R592: 34 | S592: =VLOOKUP(R592,SA!$B$5:$C$11,2,1) -> 0-35 | T592: Female | U592: Spouse | V592: 300000 | W592: =IF(U592="self",V592,0) -> 0 | X592: =IF(U592="self",1,0) -> 0 | Y592: =O592-N592+1 -> 365 | Z592: =$Z$1 -> 46081 | AA592: =IF(MIN((Z592-N592)+1,Y592)<0,0,MIN((Z592-N592)+1,Y592)) -> 264 | AB592: Delhi | AC592: =AE592+AF592+AG592+AH592 -> 3874.2114 | AD592: 1 | AE592: =IFERROR(INDEX(SA!$C$4:$E$11,MATCH(Details!S592,SA!$C$4:$C$11,0),MATCH(Details!V592,SA!$C$4:$E$4,0)),0)*Y592/(F592-E592+1) -> 3283.23 | AF592: =IF(AB592="Karnataka",AE592*9%,0) -> 0 | AG592: =IF(AB592="Karnataka",AE592*9%,0) -> 0 | AH592: =IF(AF592+AG592>0,0,AE592*18%) -> 590.9814 | AI592: =AE592*L592 -> 131.3292 | AJ592: =$AE592*M592 -> 738.72675 | AK592: =(AE592)*AA592/Y592 -> 2374.7198 | AL592: =AK592*(1-L592-M592) -> 1745.419 | AM592: =AE592-AI592-AL592-AJ592 -> 667.75501 | AN592: =Z592-366 -> 45715 | AO592: =IF(AND(O592>Z592,N592>AN592),AE592,0) -> 3283.23
A593: Valid | B593: 202506 | C593: GMC021090100AV | D593: A V GLOBAL CORPORATION PRIVATE LIMITED | E593: 45818 | F593: 46182 | G593: Pankaj Sharma | H593: AVGCT5 | I593: 31693 | J593: ACK.F683A520250231.1 | K593: =N593 -> 45818 | L593: =IF(K593>=DATE(2022,4,1),4%,5%) -> 0.04 | M593: 0.225 | N593: 45818 | O593: 46182 | R593: 38 | S593: =VLOOKUP(R593,SA!$B$5:$C$11,2,1) -> 36-45 | T593: Male | U593: Self | V593: 300000 | W593: =IF(U593="self",V593,0) -> 300000 | X593: =IF(U593="self",1,0) -> 1 | Y593: =O593-N593+1 -> 365 | Z593: =$Z$1 -> 46081 | AA593: =IF(MIN((Z593-N593)+1,Y593)<0,0,MIN((Z593-N593)+1,Y593)) -> 264 | AB593: Delhi | AC593: =AE593+AF593+AG593+AH593 -> 5017.3246 | AD593: 1 | AE593: =IFERROR(INDEX(SA!$C$4:$E$11,MATCH(Details!S593,SA!$C$4:$C$11,0),MATCH(Details!V593,SA!$C$4:$E$4,0)),0)*Y593/(F593-E593+1) -> 4251.97 | AF593: =IF(AB593="Karnataka",AE593*9%,0) -> 0 | AG593: =IF(AB593="Karnataka",AE593*9%,0) -> 0 | AH593: =IF(AF593+AG593>0,0,AE593*18%) -> 765.3546 | AI593: =AE593*L593 -> 170.0788 | AJ593: =$AE593*M593 -> 956.69325 | AK593: =(AE593)*AA593/Y593 -> 3075.3975 | AL593: =AK593*(1-L593-M593) -> 2260.4171 | AM593: =AE593-AI593-AL593-AJ593 -> 864.7808 | AN593: =Z593-366 -> 45715 | AO593: =IF(AND(O593>Z593,N593>AN593),AE593,0) -> 4251.97
A594: Valid | B594: 202506 | C594: GMC021090100AV | D594: A V GLOBAL CORPORATION PRIVATE LIMITED | E594: 45818 | F594: 46182 | G594: Prakash Kumar | H594: AVGCT6 | I594: 33785 | J594: ACK.F683A520250232.1 | K594: =N594 -> 45818 | L594: =IF(K594>=DATE(2022,4,1),4%,5%) -> 0.04 | M594: 0.225 | N594: 45818 | O594: 46182 | R594: 32 | S594: =VLOOKUP(R594,SA!$B$5:$C$11,2,1) -> 0-35 | T594: Male | U594: Self | V594: 300000 | W594: =IF(U594="self",V594,0) -> 300000 | X594: =IF(U594="self",1,0) -> 1 | Y594: =O594-N594+1 -> 365 | Z594: =$Z$1 -> 46081 | AA594: =IF(MIN((Z594-N594)+1,Y594)<0,0,MIN((Z594-N594)+1,Y594)) -> 264 | AB594: Delhi | AC594: =AE594+AF594+AG594+AH594 -> 3874.2114 | AD594: 1 | AE594: =IFERROR(INDEX(SA!$C$4:$E$11,MATCH(Details!S594,SA!$C$4:$C$11,0),MATCH(Details!V594,SA!$C$4:$E$4,0)),0)*Y594/(F594-E594+1) -> 3283.23 | AF594: =IF(AB594="Karnataka",AE594*9%,0) -> 0 | AG594: =IF(AB594="Karnataka",AE594*9%,0) -> 0 | AH594: =IF(AF594+AG594>0,0,AE594*18%) -> 590.9814 | AI594: =AE594*L594 -> 131.3292 | AJ594: =$AE594*M594 -> 738.72675 | AK594: =(AE594)*AA594/Y594 -> 2374.7198 | AL594: =AK594*(1-L594-M594) -> 1745.419 | AM594: =AE594-AI594-AL594-AJ594 -> 667.75501 | AN594: =Z594-366 -> 45715 | AO594: =IF(AND(O594>Z594,N594>AN594),AE594,0) -> 3283.23
... A596: Valid | B596: 202506 | C596: GMC021090100AV | D596: A V GLOBAL CORPORATION PRIVATE LIMITED | E596: 45818 | F596: 46182 | G596: Viraj Kashyap | H596: AVGCT6 | I596: 45036 | J596: ACK.F683A520250232.3 | K596: =N596 -> 45818 | L596: =IF(K596>=DATE(2022,4,1),4%,5%) -> 0.04 | M596: 0.225 | N596: 45818 | O596: 46182 | R596: 2 | S596: =VLOOKUP(R596,SA!$B$5:$C$11,2,1) -> 0-35 | T596: Male | U596: Son | V596: 300000 | W596: =IF(U596="self",V596,0) -> 0 | X596: =IF(U596="self",1,0) -> 0 | Y596: =O596-N596+1 -> 365 | Z596: =$Z$1 -> 46081 | AA596: =IF(MIN((Z596-N596)+1,Y596)<0,0,MIN((Z596-N596)+1,Y596)) -> 264 | AB596: Delhi | AC596: =AE596+AF596+AG596+AH596 -> 3874.2114 | AD596: 1 | AE596: =IFERROR(INDEX(SA!$C$4:$E$11,MATCH(Details!S596,SA!$C$4:$C$11,0),MATCH(Details!V596,SA!$C$4:$E$4,0)),0)*Y596/(F596-E596+1) -> 3283.23 | AF596: =IF(AB596="Karnataka",AE596*9%,0) -> 0 | AG596: =IF(AB596="Karnataka",AE596*9%,0) -> 0 | AH596: =IF(AF596+AG596>0,0,AE596*18%) -> 590.9814 | AI596: =AE596*L596 -> 131.3292 | AJ596: =$AE596*M596 -> 738.72675 | AK596: =(AE596)*AA596/Y596 -> 2374.7198 | AL596: =AK596*(1-L596-M596) -> 1745.419 | AM596: =AE596-AI596-AL596-AJ596 -> 667.75501 | AN596: =Z596-366 -> 45715 | AO596: =IF(AND(O596>Z596,N596>AN596),AE596,0) -> 3283.23
A597: Valid | B597: 202506 | C597: GMC021090100AV | D597: A V GLOBAL CORPORATION PRIVATE LIMITED | E597: 45818 | F597: 46182 | G597: Sgurusaran | H597: 2327 | I597: 35603 | J597: ACK.F683A520250207.1 | K597: =N597 -> 45818 | L597: =IF(K597>=DATE(2022,4,1),4%,5%) -> 0.04 | M597: 0.225 | N597: 45818 | O597: 46182 | R597: 27 | S597: =VLOOKUP(R597,SA!$B$5:$C$11,2,1) -> 0-35 | T597: Male | U597: Self | V597: 300000 | W597: =IF(U597="self",V597,0) -> 300000 | X597: =IF(U597="self",1,0) -> 1 | Y597: =O597-N597+1 -> 365 | Z597: =$Z$1 -> 46081 | AA597: =IF(MIN((Z597-N597)+1,Y597)<0,0,MIN((Z597-N597)+1,Y597)) -> 264 | AB597: Delhi | AC597: =AE597+AF597+AG597+AH597 -> 3874.2114 | AD597: 1 | AE597: =IFERROR(INDEX(SA!$C$4:$E$11,MATCH(Details!S597,SA!$C$4:$C$11,0),MATCH(Details!V597,SA!$C$4:$E$4,0)),0)*Y597/(F597-E597+1) -> 3283.23 | AF597: =IF(AB597="Karnataka",AE597*9%,0) -> 0 | AG597: =IF(AB597="Karnataka",AE597*9%,0) -> 0 | AH597: =IF(AF597+AG597>0,0,AE597*18%) -> 590.9814 | AI597: =AE597*L597 -> 131.3292 | AJ597: =$AE597*M597 -> 738.72675 | AK597: =(AE597)*AA597/Y597 -> 2374.7198 | AL597: =AK597*(1-L597-M597) -> 1745.419 | AM597: =AE597-AI597-AL597-AJ597 -> 667.75501 | AN597: =Z597-366 -> 45715 | AO597: =IF(AND(O597>Z597,N597>AN597),AE597,0) -> 3283.23
A598: Valid | B598: 202506 | C598: GMC021090100AV | D598: A V GLOBAL CORPORATION PRIVATE LIMITED | E598: 45818 | F598: 46182 | G598: Subbulakshmi Krishnamoorthy | H598: 2327 | I598: 38129 | J598: ACK.F683A520250207.2 | K598: =N598 -> 45818 | L598: =IF(K598>=DATE(2022,4,1),4%,5%) -> 0.04 | M598: 0.225 | N598: 45818 | O598: 46182 | R598: 21 | S598: =VLOOKUP(R598,SA!$B$5:$C$11,2,1) -> 0-35 | T598: Female | U598: Spouse | V598: 300000 | W598: =IF(U598="self",V598,0) -> 0 | X598: =IF(U598="self",1,0) -> 0 | Y598: =O598-N598+1 -> 365 | Z598: =$Z$1 -> 46081 | AA598: =IF(MIN((Z598-N598)+1,Y598)<0,0,MIN((Z598-N598)+1,Y598)) -> 264 | AB598: Delhi | AC598: =AE598+AF598+AG598+AH598 -> 3874.2114 | AD598: 1 | AE598: =IFERROR(INDEX(SA!$C$4:$E$11,MATCH(Details!S598,SA!$C$4:$C$11,0),MATCH(Details!V598,SA!$C$4:$E$4,0)),0)*Y598/(F598-E598+1) -> 3283.23 | AF598: =IF(AB598="Karnataka",AE598*9%,0) -> 0 | AG598: =IF(AB598="Karnataka",AE598*9%,0) -> 0 | AH598: =IF(AF598+AG598>0,0,AE598*18%) -> 590.9814 | AI598: =AE598*L598 -> 131.3292 | AJ598: =$AE598*M598 -> 738.72675 | AK598: =(AE598)*AA598/Y598 -> 2374.7198 | AL598: =AK598*(1-L598-M598) -> 1745.419 | AM598: =AE598-AI598-AL598-AJ598 -> 667.75501 | AN598: =Z598-366 -> 45715 | AO598: =IF(AND(O598>Z598,N598>AN598),AE598,0) -> 3283.23
A599: Valid | B599: 202506 | C599: GMC021090100AV | D599: A V GLOBAL CORPORATION PRIVATE LIMITED | E599: 45818 | F599: 46182 | G599: Abhishek Kumar | H599: 2324 | I599: 35189 | J599: ACK.F683A520250204.1 | K599: =N599 -> 45818 | L599: =IF(K599>=DATE(2022,4,1),4%,5%) -> 0.04 | M599: 0.225 | N599: 45818 | O599: 46182 | R599: 29 | S599: =VLOOKUP(R599,SA!$B$5:$C$11,2,1) -> 0-35 | T599: Male | U599: Self | V599: 300000 | W599: =IF(U599="self",V599,0) -> 300000 | X599: =IF(U599="self",1,0) -> 1 | Y599: =O599-N599+1 -> 365 | Z599: =$Z$1 -> 46081 | AA599: =IF(MIN((Z599-N599)+1,Y599)<0,0,MIN((Z599-N599)+1,Y599)) -> 264 | AB599: Delhi | AC599: =AE599+AF599+AG599+AH599 -> 3874.2114 | AD599: 1 | AE599: =IFERROR(INDEX(SA!$C$4:$E$11,MATCH(Details!S599,SA!$C$4:$C$11,0),MATCH(Details!V599,SA!$C$4:$E$4,0)),0)*Y599/(F599-E599+1) -> 3283.23 | AF599: =IF(AB599="Karnataka",AE599*9%,0) -> 0 | AG599: =IF(AB599="Karnataka",AE599*9%,0) -> 0 | AH599: =IF(AF599+AG599>0,0,AE599*18%) -> 590.9814 | AI599: =AE599*L599 -> 131.3292 | AJ599: =$AE599*M599 -> 738.72675 | AK599: =(AE599)*AA599/Y599 -> 2374.7198 | AL599: =AK599*(1-L599-M599) -> 1745.419 | AM599: =AE599-AI599-AL599-AJ599 -> 667.75501 | AN599: =Z599-366 -> 45715 | AO599: =IF(AND(O599>Z599,N599>AN599),AE599,0) -> 3283.23
A600: Valid | B600: 202506 | C600: GMC021090100AV | D600: A V GLOBAL CORPORATION PRIVATE LIMITED | E600: 45818 | F600: 46182 | G600: Shweta Kumari | H600: 2324 | I600: 36222 | J600: ACK.F683A520250204.2 | K600: =N600 -> 45818 | L600: =IF(K600>=DATE(2022,4,1),4%,5%) -> 0.04 | M600: 0.225 | N600: 45818 | O600: 46182 | R600: 26 | S600: =VLOOKUP(R600,SA!$B$5:$C$11,2,1) -> 0-35 | T600: Female | U600: Spouse | V600: 300000 | W600: =IF(U600="self",V600,0) -> 0 | X600: =IF(U600="self",1,0) -> 0 | Y600: =O600-N600+1 -> 365 | Z600: =$Z$1 -> 46081 | AA600: =IF(MIN((Z600-N600)+1,Y600)<0,0,MIN((Z600-N600)+1,Y600)) -> 264 | AB600: Delhi | AC600: =AE600+AF600+AG600+AH600 -> 3874.2114 | AD600: 1 | AE600: =IFERROR(INDEX(SA!$C$4:$E$11,MATCH(Details!S600,SA!$C$4:$C$11,0),MATCH(Details!V600,SA!$C$4:$E$4,0)),0)*Y600/(F600-E600+1) -> 3283.23 | AF600: =IF(AB600="Karnataka",AE600*9%,0) -> 0 | AG600: =IF(AB600="Karnataka",AE600*9%,0) -> 0 | AH600: =IF(AF600+AG600>0,0,AE600*18%) -> 590.9814 | AI600: =AE600*L600 -> 131.3292 | AJ600: =$AE600*M600 -> 738.72675 | AK600: =(AE600)*AA600/Y600 -> 2374.7198 | AL600: =AK600*(1-L600-M600) -> 1745.419 | AM600: =AE600-AI600-AL600-AJ600 -> 667.75501 | AN600: =Z600-366 -> 45715 | AO600: =IF(AND(O600>Z600,N600>AN600),AE600,0) -> 3283.23
A601: Valid | B601: 202506 | C601: GMC021090100AV | D601: A V GLOBAL CORPORATION PRIVATE LIMITED | E601: 45818 | F601: 46182 | G601: Aradhya Kumari | H601: 2324 | I601: 43084 | J601: ACK.F683A520250204.3 | K601: =N601 -> 45818 | L601: =IF(K601>=DATE(2022,4,1),4%,5%) -> 0.04 | M601: 0.225 | N601: 45818 | O601: 46182 | R601: 7 | S601: =VLOOKUP(R601,SA!$B$5:$C$11,2,1) -> 0-35 | T601: Female | U601: Daughter | V601: 300000 | W601: =IF(U601="self",V601,0) -> 0 | X601: =IF(U601="self",1,0) -> 0 | Y601: =O601-N601+1 -> 365 | Z601: =$Z$1 -> 46081 | AA601: =IF(MIN((Z601-N601)+1,Y601)<0,0,MIN((Z601-N601)+1,Y601)) -> 264 | AB601: Delhi | AC601: =AE601+AF601+AG601+AH601 -> 3874.2114 | AD601: 1 | AE601: =IFERROR(INDEX(SA!$C$4:$E$11,MATCH(Details!S601,SA!$C$4:$C$11,0),MATCH(Details!V601,SA!$C$4:$E$4,0)),0)*Y601/(F601-E601+1) -> 3283.23 | AF601: =IF(AB601="Karnataka",AE601*9%,0) -> 0 | AG601: =IF(AB601="Karnataka",AE601*9%,0) -> 0 | AH601: =IF(AF601+AG601>0,0,AE601*18%) -> 590.9814 | AI601: =AE601*L601 -> 131.3292 | AJ601: =$AE601*M601 -> 738.72675 | AK601: =(AE601)*AA601/Y601 -> 2374.7198 | AL601: =AK601*(1-L601-M601) -> 1745.419 | AM601: =AE601-AI601-AL601-AJ601 -> 667.75501 | AN601: =Z601-366 -> 45715 | AO601: =IF(AND(O601>Z601,N601>AN601),AE601,0) -> 3283.23
A602: Valid | B602: 202506 | C602: GMC021090100AV | D602: A V GLOBAL CORPORATION PRIVATE LIMITED | E602: 45818 | F602: 46182 | G602: Lakshya Kashyap | H602: 2324 | I602: 43860 | J602: ACK.F683A520250204.4 | K602: =N602 -> 45818 | L602: =IF(K602>=DATE(2022,4,1),4%,5%) -> 0.04 | M602: 0.225 | N602: 45818 | O602: 46182 | R602: 5 | S602: =VLOOKUP(R602,SA!$B$5:$C$11,2,1) -> 0-35 | T602: Male | U602: Son | V602: 300000 | W602: =IF(U602="self",V602,0) -> 0 | X602: =IF(U602="self",1,0) -> 0 | Y602: =O602-N602+1 -> 365 | Z602: =$Z$1 -> 46081 | AA602: =IF(MIN((Z602-N602)+1,Y602)<0,0,MIN((Z602-N602)+1,Y602)) -> 264 | AB602: Delhi | AC602: =AE602+AF602+AG602+AH602 -> 3874.2114 | AD602: 1 | AE602: =IFERROR(INDEX(SA!$C$4:$E$11,MATCH(Details!S602,SA!$C$4:$C$11,0),MATCH(Details!V602,SA!$C$4:$E$4,0)),0)*Y602/(F602-E602+1) -> 3283.23 | AF602: =IF(AB602="Karnataka",AE602*9%,0) -> 0 | AG602: =IF(AB602="Karnataka",AE602*9%,0) -> 0 | AH602: =IF(AF602+AG602>0,0,AE602*18%) -> 590.9814 | AI602: =AE602*L602 -> 131.3292 | AJ602: =$AE602*M602 -> 738.72675 | AK602: =(AE602)*AA602/Y602 -> 2374.7198 | AL602: =AK602*(1-L602-M602) -> 1745.419 | AM602: =AE602-AI602-AL602-AJ602 -> 667.75501 | AN602: =Z602-366 -> 45715 | AO602: =IF(AND(O602>Z602,N602>AN602),AE602,0) -> 3283.23
A603: Valid | B603: 202506 | C603: GMC021090100AV | D603: A V GLOBAL CORPORATION PRIVATE LIMITED | E603: 45818 | F603: 46182 | G603: Anand Kumar S | H603: 2215 | I603: 33150 | J603: ACK.F683A520250141.1 | K603: =N603 -> 45818 | L603: =IF(K603>=DATE(2022,4,1),4%,5%) -> 0.04 | M603: 0.225 | N603: 45818 | O603: 46182 | R603: 34 | S603: =VLOOKUP(R603,SA!$B$5:$C$11,2,1) -> 0-35 | T603: Male | U603: Self | V603: 300000 | W603: =IF(U603="self",V603,0) -> 300000 | X603: =IF(U603="self",1,0) -> 1 | Y603: =O603-N603+1 -> 365 | Z603: =$Z$1 -> 46081 | AA603: =IF(MIN((Z603-N603)+1,Y603)<0,0,MIN((Z603-N603)+1,Y603)) -> 264 | AB603: Delhi | AC603: =AE603+AF603+AG603+AH603 -> 3874.2114 | AD603: 1 | AE603: =IFERROR(INDEX(SA!$C$4:$E$11,MATCH(Details!S603,SA!$C$4:$C$11,0),MATCH(Details!V603,SA!$C$4:$E$4,0)),0)*Y603/(F603-E603+1) -> 3283.23 | AF603: =IF(AB603="Karnataka",AE603*9%,0) -> 0 | AG603: =IF(AB603="Karnataka",AE603*9%,0) -> 0 | AH603: =IF(AF603+AG603>0,0,AE603*18%) -> 590.9814 | AI603: =AE603*L603 -> 131.3292 | AJ603: =$AE603*M603 -> 738.72675 | AK603: =(AE603)*AA603/Y603 -> 2374.7198 | AL603: =AK603*(1-L603-M603) -> 1745.419 | AM603: =AE603-AI603-AL603-AJ603 -> 667.75501 | AN603: =Z603-366 -> 45715 | AO603: =IF(AND(O603>Z603,N603>AN603),AE603,0) -> 3283.23
A604: Valid | B604: 202506 | C604: GMC021090100AV | D604: A V GLOBAL CORPORATION PRIVATE LIMITED | E604: 45818 | F604: 46182 | G604: Nagashree N S | H604: 2215 | I604: 34132 | J604: ACK.F683A520250141.2 | K604: =N604 -> 45818 | L604: =IF(K604>=DATE(2022,4,1),4%,5%) -> 0.04 | M604: 0.225 | N604: 45818 | O604: 46182 | R604: 31 | S604: =VLOOKUP(R604,SA!$B$5:$C$11,2,1) -> 0-35 | T604: Female | U604: Spouse | V604: 300000 | W604: =IF(U604="self",V604,0) -> 0 | X604: =IF(U604="self",1,0) -> 0 | Y604: =O604-N604+1 -> 365 | Z604: =$Z$1 -> 46081 | AA604: =IF(MIN((Z604-N604)+1,Y604)<0,0,MIN((Z604-N604)+1,Y604)) -> 264 | AB604: Delhi | AC604: =AE604+AF604+AG604+AH604 -> 3874.2114 | AD604: 1 | AE604: =IFERROR(INDEX(SA!$C$4:$E$11,MATCH(Details!S604,SA!$C$4:$C$11,0),MATCH(Details!V604,SA!$C$4:$E$4,0)),0)*Y604/(F604-E604+1) -> 3283.23 | AF604: =IF(AB604="Karnataka",AE604*9%,0) -> 0 | AG604: =IF(AB604="Karnataka",AE604*9%,0) -> 0 | AH604: =IF(AF604+AG604>0,0,AE604*18%) -> 590.9814 | AI604: =AE604*L604 -> 131.3292 | AJ604: =$AE604*M604 -> 738.72675 | AK604: =(AE604)*AA604/Y604 -> 2374.7198 | AL604: =AK604*(1-L604-M604) -> 1745.419 | AM604: =AE604-AI604-AL604-AJ604 -> 667.75501 | AN604: =Z604-366 -> 45715 | AO604: =IF(AND(O604>Z604,N604>AN604),AE604,0) -> 3283.23
A605: Valid | B605: 202506 | C605: GMC021090100AV | D605: A V GLOBAL CORPORATION PRIVATE LIMITED | E605: 45818 | F605: 46182 | G605: Niharika Anand | H605: 2215 | I605: 43933 | J605: ACK.F683A520250141.3 | K605: =N605 -> 45818 | L605: =IF(K605>=DATE(2022,4,1),4%,5%) -> 0.04 | M605: 0.225 | N605: 45818 | O605: 46182 | R605: 5 | S605: =VLOOKUP(R605,SA!$B$5:$C$11,2,1) -> 0-35 | T605: Female | U605: Daughter | V605: 300000 | W605: =IF(U605="self",V605,0) -> 0 | X605: =IF(U605="self",1,0) -> 0 | Y605: =O605-N605+1 -> 365 | Z605: =$Z$1 -> 46081 | AA605: =IF(MIN((Z605-N605)+1,Y605)<0,0,MIN((Z605-N605)+1,Y605)) -> 264 | AB605: Delhi | AC605: =AE605+AF605+AG605+AH605 -> 3874.2114 | AD605: 1 | AE605: =IFERROR(INDEX(SA!$C$4:$E$11,MATCH(Details!S605,SA!$C$4:$C$11,0),MATCH(Details!V605,SA!$C$4:$E$4,0)),0)*Y605/(F605-E605+1) -> 3283.23 | AF605: =IF(AB605="Karnataka",AE605*9%,0) -> 0 | AG605: =IF(AB605="Karnataka",AE605*9%,0) -> 0 | AH605: =IF(AF605+AG605>0,0,AE605*18%) -> 590.9814 | AI605: =AE605*L605 -> 131.3292 | AJ605: =$AE605*M605 -> 738.72675 | AK605: =(AE605)*AA605/Y605 -> 2374.7198 | AL605: =AK605*(1-L605-M605) -> 1745.419 | AM605: =AE605-AI605-AL605-AJ605 -> 667.75501 | AN605: =Z605-366 -> 45715 | AO605: =IF(AND(O605>Z605,N605>AN605),AE605,0) -> 3283.23
A606: Valid | B606: 202506 | C606: GMC021090100AV | D606: A V GLOBAL CORPORATION PRIVATE LIMITED | E606: 45818 | F606: 46182 | G606: Pradeep N A | H606: 2229 | I606: 32187 | J606: ACK.F683A520250147.1 | K606: =N606 -> 45818 | L606: =IF(K606>=DATE(2022,4,1),4%,5%) -> 0.04 | M606: 0.225 | N606: 45818 | O606: 46182 | R606: 37 | S606: =VLOOKUP(R606,SA!$B$5:$C$11,2,1) -> 36-45 | T606: Male | U606: Self | V606: 300000 | W606: =IF(U606="self",V606,0) -> 300000 | X606: =IF(U606="self",1,0) -> 1 | Y606: =O606-N606+1 -> 365 | Z606: =$Z$1 -> 46081 | AA606: =IF(MIN((Z606-N606)+1,Y606)<0,0,MIN((Z606-N606)+1,Y606)) -> 264 | AB606: Delhi | AC606: =AE606+AF606+AG606+AH606 -> 5017.3246 | AD606: 1 | AE606: =IFERROR(INDEX(SA!$C$4:$E$11,MATCH(Details!S606,SA!$C$4:$C$11,0),MATCH(Details!V606,SA!$C$4:$E$4,0)),0)*Y606/(F606-E606+1) -> 4251.97 | AF606: =IF(AB606="Karnataka",AE606*9%,0) -> 0 | AG606: =IF(AB606="Karnataka",AE606*9%,0) -> 0 | AH606: =IF(AF606+AG606>0,0,AE606*18%) -> 765.3546 | AI606: =AE606*L606 -> 170.0788 | AJ606: =$AE606*M606 -> 956.69325 | AK606: =(AE606)*AA606/Y606 -> 3075.3975 | AL606: =AK606*(1-L606-M606) -> 2260.4171 | AM606: =AE606-AI606-AL606-AJ606 -> 864.7808 | AN606: =Z606-366 -> 45715 | AO606: =IF(AND(O606>Z606,N606>AN606),AE606,0) -> 4251.97
A607: Valid | B607: 202506 | C607: GMC021090100AV | D607: A V GLOBAL CORPORATION PRIVATE LIMITED | E607: 45818 | F607: 46182 | G607: Kavya K | H607: 2229 | I607: 32750 | J607: ACK.F683A520250147.2 | K607: =N607 -> 45818 | L607: =IF(K607>=DATE(2022,4,1),4%,5%) -> 0.04 | M607: 0.225 | N607: 45818 | O607: 46182 | R607: 35 | S607: =VLOOKUP(R607,SA!$B$5:$C$11,2,1) -> 0-35 | T607: Female | U607: Spouse | V607: 300000 | W607: =IF(U607="self",V607,0) -> 0 | X607: =IF(U607="self",1,0) -> 0 | Y607: =O607-N607+1 -> 365 | Z607: =$Z$1 -> 46081 | AA607: =IF(MIN((Z607-N607)+1,Y607)<0,0,MIN((Z607-N607)+1,Y607)) -> 264 | AB607: Delhi | AC607: =AE607+AF607+AG607+AH607 -> 3874.2114 | AD607: 1 | AE607: =IFERROR(INDEX(SA!$C$4:$E$11,MATCH(Details!S607,SA!$C$4:$C$11,0),MATCH(Details!V607,SA!$C$4:$E$4,0)),0)*Y607/(F607-E607+1) -> 3283.23 | AF607: =IF(AB607="Karnataka",AE607*9%,0) -> 0 | AG607: =IF(AB607="Karnataka",AE607*9%,0) -> 0 | AH607: =IF(AF607+AG607>0,0,AE607*18%) -> 590.9814 | AI607: =AE607*L607 -> 131.3292 | AJ607: =$AE607*M607 -> 738.72675 | AK607: =(AE607)*AA607/Y607 -> 2374.7198 | AL607: =AK607*(1-L607-M607) -> 1745.419 | AM607: =AE607-AI607-AL607-AJ607 -> 667.75501 | AN607: =Z607-366 -> 45715 | AO607: =IF(AND(O607>Z607,N607>AN607),AE607,0) -> 3283.23
A608: Valid | B608: 202506 | C608: GMC021090100AV | D608: A V GLOBAL CORPORATION PRIVATE LIMITED | E608: 45818 | F608: 46182 | G608: Rupesh Waman Kadam | H608: 2337 | I608: 30175 | J608: ACK.F683A520250215.1 | K608: =N608 -> 45818 | L608: =IF(K608>=DATE(2022,4,1),4%,5%) -> 0.04 | M608: 0.225 | N608: 45818 | O608: 46182 | R608: 42 | S608: =VLOOKUP(R608,SA!$B$5:$C$11,2,1) -> 36-45 | T608: Male | U608: Self | V608: 300000 | W608: =IF(U608="self",V608,0) -> 300000 | X608: =IF(U608="self",1,0) -> 1 | Y608: =O608-N608+1 -> 365 | Z608: =$Z$1 -> 46081 | AA608: =IF(MIN((Z608-N608)+1,Y608)<0,0,MIN((Z608-N608)+1,Y608)) -> 264 | AB608: Delhi | AC608: =AE608+AF608+AG608+AH608 -> 5017.3246 | AD608: 1 | AE608: =IFERROR(INDEX(SA!$C$4:$E$11,MATCH(Details!S608,SA!$C$4:$C$11,0),MATCH(Details!V608,SA!$C$4:$E$4,0)),0)*Y608/(F608-E608+1) -> 4251.97 | AF608: =IF(AB608="Karnataka",AE608*9%,0) -> 0 | AG608: =IF(AB608="Karnataka",AE608*9%,0) -> 0 | AH608: =IF(AF608+AG608>0,0,AE608*18%) -> 765.3546 | AI608: =AE608*L608 -> 170.0788 | AJ608: =$AE608*M608 -> 956.69325 | AK608: =(AE608)*AA608/Y608 -> 3075.3975 | AL608: =AK608*(1-L608-M608) -> 2260.4171 | AM608: =AE608-AI608-AL608-AJ608 -> 864.7808 | AN608: =Z608-366 -> 45715 | AO608: =IF(AND(O608>Z608,N608>AN608),AE608,0) -> 4251.97
...

Sheet CD Statement
B5: Acko General Insurance Limited
B6: CD Utilization Statement as on 28th Feb 2026
B7: Date | C7: Premium | D7: Tax Invoice No | E7: Description | F7: APD | G7: Balance
B8: 45815 | E8: HDFCH00289610341/AVGLOBA1/A V GLOBAL CORPORATION P LTD | F8: 3633220 | G8: =F8 -> 3633220
B9: 45828 | C9: 3633220.2 | D9: GMC021090100 | E9: GMC Premium | G9: =G8+F9-C9 -> -0.2006
B10: 45838 | G10: =G9+F10-C10 -> -0.2006
B11: 45856 | E11: HDFCH00372273827/AVGLOBA1/A V GLOBAL CORPORATION P LTD | F11: 100000 | G11: =G10+F11-C11 -> 99999.799
B12: 45867 | C12: 63385.809 | D12: GMC021090101 | E12: GMC Premium | G12: =G11+F12-C12 -> 36613.99
B13: 45869 | G13: =G12+F13-C13 -> 36613.99
B14: 45876 | C14: 29815.159 | D14: GMC021090102 | E14: GMC Premium | G14: =G13+F14-C14 -> 6798.8311
B15: 45889 | C15: 0 | D15: GMC021090103 | E15: GMC Premium | G15: =G14+F15-C15 -> 6798.8311
B16: 45900 | C16: 0 | D16: GMC021090104 | E16: GMC Premium | G16: =G15+F16-C16 -> 6798.8311
B17: 45900 | G17: =G16+F17-C17 -> 6798.8311
B18: 45911 | C18: 0 | D18: GMC021090105 | E18: GMC Premium | G18: =G17+F18-C18 -> 6798.8311
B19: 45911 | C19: -3971.9462 | D19: GMC021090106 | E19: GMC Premium | G19: =G18+F19-C19 -> 10770.777
B20: 45913 | E20: HDFCH00484406051/AVGLOBA1/A V GLOBAL CORPORATION P LTD | F20: 100000 | G20: =G19+F20-C20 -> 110770.78
B21: 45918 | C21: 2929.5407 | D21: GMC021090107 | E21: GMC Premium | G21: =G20+F21-C21 -> 107841.24
B22: 45925 | C22: 6445.6586 | D22: GMC021090108 | E22: GMC Premium | G22: =G21+F22-C22 -> 101395.58
B23: 45930 | G23: =G22+F23-C23 -> 101395.58
B24: 45961 | C24: 62537.948 | D24: GMC021090109 | E24: GMC Premium | G24: =G23+F24-C24 -> 38857.63
B25: 45983 | C25: 3766.051 | D25: GMC021090110 | E25: GMC Premium | G25: =G24+F25-C25 -> 35091.579
B26: 45991 | G26: =G25+F26-C26 -> 35091.579
B27: 46001 | C27: 5324.5415 | D27: GMC021090111 | E27: GMC Premium | G27: =G26+F27-C27 -> 29767.038
B28: 46022 | G28: =G27+F28-C28 -> 29767.038
B29: 46053 | G29: =G28+F29-C29 -> 29767.038
B30: 46062 | C30: 17183.329 | D30: GMC021090112 | E30: GMC Premium | G30: =G29+F30-C30 -> 12583.709
B31: 46081 | G31: =G30+F31-C31 -> 12583.709 | H31: =SuM!C8+SuM!C14-SUM(C8:C36) -> 0

Sheet SA
C4: Age Band/SI | D4: 300000 | E4: 1000000
B5: 0 | C5: 0-35 | D5: 3283.23 | E5: 5393.16
B6: 36 | C6: 36-45 | D6: 4251.97 | E6: 7639.02
B7: 46 | C7: 46-55 | D7: 8124.57 | E7: 14753.81
B8: 56 | C8: 56-65 | D8: 14246.99 | E8: 26014.05
B9: 66 | C9: 66-70 | D9: 29312.24 | E9: 54664.73
B10: 71 | C10: 71-75 | D10: 30115.02 | E10: 56645.56
B11: 76 | C11: 76-80 | D11: 30993.25 | E11: 59709.69

Sheet Check
A4: Emp id | B4: Sum of No of Policies | C4: Sum of No of Person Cover Per Day | D4: a | E4: UHID | F4: Gender | G4: Relationship | H4: Sum of Reporting Sum Insured | I4: Sum of GWP | J4: Sum of No of Person Cover Per Day | K4: aa
A5: 1001 | B5: 1 | C5: 2 | E5: ACK.F683A520250005.1 | F5: Male | G5: Self | H5: 1000000 | I5: 54664.73 | J5: 1
A6: 1002 | B6: 1 | C6: 1 | E6: ACK.F683A520250005.2 | F6: Female | G6: Spouse | H6: 0 | I6: 26014.05 | J6: 1
A7: 1004 | B7: 1 | C7: 4 | E7: ACK.F683A520250002.1 | F7: Male | G7: Self | H7: 1000000 | I7: 54664.73 | J7: 1
A8: 1005 | B8: 1 | C8: 4 | E8: ACK.F683A520250003.1 | F8: Male | G8: Self | H8: 300000 | I8: 8124.57 | J8: 1
A9: 1006 | B9: 1 | C9: 3 | E9: ACK.F683A520250003.2 | F9: Male | G9: Son | H9: 0 | I9: 3283.23 | J9: 1
A10: 1007 | B10: 1 | C10: 4 | E10: ACK.F683A520250003.3 | F10: Male | G10: Son | H10: 0 | I10: 3283.23 | J10: 1
A11: 1008 | B11: 1 | C11: 3 | E11: ACK.F683A520250003.4 | F11: Female | G11: Spouse | H11: 0 | I11: 4251.97 | J11: 1
A12: 1016 | B12: 1 | C12: 3 | E12: ACK.F683A520250006.1 | F12: Male | G12: Self | H12: 300000 | I12: 8124.57 | J12: 1
A13: 1017 | B13: 1 | C13: 2 | E13: ACK.F683A520250006.2 | F13: Female | G13: Spouse | H13: 0 | I13: 4251.97 | J13: 1
A14: 1019 | B14: 1 | C14: 4 | E14: ACK.F683A520250006.3 | F14: Female | G14: Daughter | H14: 0 | I14: 3283.23 | J14: 1
A15: 1022 | B15: 1 | C15: 2 | E15: ACK.F683A520250006.4 | F15: Male | G15: Son | H15: 0 | I15: 3283.23 | J15: 1
A16: 1023 | B16: 1 | C16: 3 | E16: ACK.F683A520250004.1 | F16: Female | G16: Self | H16: 300000 | I16: 14246.99 | J16: 1
... A21: 1032 | B21: 1 | C21: 2 | E21: ACK.F683A520250010.3 | F21: Female | G21: Spouse | H21: 0 | I21: 4251.97 | J21: 1
A22: 1033 | B22: 1 | C22: 1 | E22: ACK.F683A520250010.4 | H22: 0 | I22: 3283.23 | J22: 1
A23: 1035 | B23: 1 | C23: 3 | E23: ACK.F683A520250007.1 | F23: Male | G23: Self | H23: 300000 | I23: 8124.57 | J23: 1
A24: 1036 | B24: 1 | C24: 3 | E24: ACK.F683A520250007.2 | F24: Female | G24: Spouse | H24: 0 | I24: 8124.57 | J24: 1
A25: 1044 | B25: 1 | C25: 3 | E25: ACK.F683A520250007.3 | F25: Female | G25: Daughter | H25: 0 | I25: 3283.23 | J25: 1
A26: 1047 | B26: 1 | C26: 4 | E26: ACK.F683A520250008.1 | F26: Male | G26: Self | H26: 300000 | I26: 8124.57 | J26: 1
A27: 1049 | B27: 1 | C27: 4 | E27: ACK.F683A520250008.2 | F27: Female | G27: Spouse | H27: 0 | I27: 8124.57 | J27: 1
A28: 1055 | B28: 1 | C28: 4 | E28: ACK.F683A520250008.3 | F28: Male | G28: Son | H28: 0 | I28: 3283.23 | J28: 1
A29: 1056 | B29: 1 | C29: 3 | E29: ACK.F683A520250009.1 | F29: Male | G29: Self | H29: 300000 | I29: 8124.57 | J29: 1
A30: 1057 | B30: 1 | C30: 4 | E30: ACK.F683A520250009.2 | F30: Female | G30: Spouse | H30: 0 | I30: 8124.57 | J30: 1
A31: 1059 | B31: 1 | C31: 4 | E31: ACK.F683A520250011.1 | F31: Male | G31: Self | H31: 300000 | I31: 8124.57 | J31: 1
A32: 1060 | B32: 1 | C32: 4 | E32: ACK.F683A520250011.2 | F32: Female | G32: Daughter | H32: 0 | I32: 3283.23 | J32: 1
A33: 1061 | B33: 1 | C33: 4 | E33: ACK.F683A520250011.3 | F33: Female | G33: Daughter | H33: 0 | I33: 3283.23 | J33: 1
A34: 1062 | B34: 1 | C34: 3 | E34: ACK.F683A520250011.4 | F34: Female | G34: Spouse | H34: 0 | I34: 8124.57 | J34: 1
... A202: 4019 | B202: 1 | C202: 4 | E202: ACK.F683A520250065.4 | F202: Male | G202: Son | H202: 0 | I202: 3283.23 | J202: 1
A203: AVGCT1 | B203: 1 | C203: 3 | E203: ACK.F683A520250064.1 | F203: Male | G203: Self | H203: 300000 | I203: 4251.97 | J203: 1
A204: AVGCT2 | B204: 1 | C204: 4 | E204: ACK.F683A520250064.2 | F204: Male | G204: Son | H204: 0 | I204: 3283.23 | J204: 1
A205: AVGCT3 | B205: 0 | C205: 0 | E205: ACK.F683A520250064.3 | F205: Female | G205: Daughter | H205: 0 | I205: 3283.23 | J205: 1
