Workbook

Sheet Performance
F2: Health ( INR Lakhs) | G2: M01'19
F3: GWP | G3: =SuM!C8/100000 -> 225.52506
F4: NEP | G4: =SuM!C26/100000 -> 81.101078
F5: Claims (excluding IBNR)-33% of NEP | G5: =((60760+23748)*0.95)/100000 -> 0.802826 | I5: =G5*100000/G9 -> 743.35741
F6: Claims (including IBNR)-95% of NEP | G6: =((60760+23748)*0.95+154370)/100000 -> 2.346526
F7: Claims service cost(3% of claims) | G7: =3%*G6 -> 0.07039578
F8: No. of Policies | G8: 1592
F9: No. of Claims | G9: 108

Sheet SuM
A1: =C41&":" -> CALDERYS INDIA REFRACTORIES LIMITED:
A2: Particulars | C2: Number/₹ | D2: 202602
A3: No of Lives Insured | C3: =SUMIF(Details!B:B,$D$2,Details!AD:AD) -> 45
A4: GWP excl GST | C4: =SUMIF(Details!B:B,$D$2,Details!AE:AE) -> 172165.32
A6: Particulars | B6: Details | C6: Total | E6: 45901 | F6: 45931 | G6: 45962 | H6: 45992 | I6: 46023 | J6: 46054 | K6: 46082 | L6: 46113 | M6: 46143 | N6: 46174 | O6: 46204 | P6: 46235 | Q6: 46266 | R6: 46296 | S6: 46327 | U6: Recon
A8: GWP | C8: =Details!AE1 -> 22552506 | E8: 21745013 | F8: -18739.698 | G8: 448900.47 | H8: 66325.505 | I8: 138841.14 | J8: =SUMIF(Details!$B:$B,$D$2,Details!$AE:$AE) -> 172165.32 | K8: =SUMIF(Details!$B:$B,$D$2,Details!$AE:$AE) -> 172165.32 | L8: =SUMIF(Details!$B:$B,$D$2,Details!$AE:$AE) -> 172165.32 | M8: =SUMIF(Details!$B:$B,$D$2,Details!$AE:$AE) -> 172165.32 | N8: =SUMIF(Details!$B:$B,$D$2,Details!$AE:$AE) -> 172165.32 | O8: =SUMIF(Details!$B:$B,$D$2,Details!$AE:$AE) -> 172165.32 | P8: =SUMIF(Details!$B:$B,$D$2,Details!$AE:$AE) -> 172165.32 | Q8: =SUMIF(Details!$B:$B,$D$2,Details!$AE:$AE) -> 172165.32 | ... S8: =SUMIF(Details!$B:$B,$D$2,Details!$AE:$AE) -> 172165.32 | U8: =$C8-SUM(E8:J8) -> 4.8428774e-08
U9: =$C9-SUM(E9:J9) -> 0
A10: GST: | U10: =$C10-SUM(E10:J10) -> 0
A11: SGST/UGST | C11: =Details!AF1 -> 0 | E11: 0 | F11: 0 | G11: 0 | H11: 0 | I11: 0 | J11: =SUMIF(Details!$B:$B,$D$2,Details!$AF:$AF) -> 0 | K11: =SUMIF(Details!$B:$B,$D$2,Details!$AF:$AF) -> 0 | L11: =SUMIF(Details!$B:$B,$D$2,Details!$AF:$AF) -> 0 | M11: =SUMIF(Details!$B:$B,$D$2,Details!$AF:$AF) -> 0 | N11: =SUMIF(Details!$B:$B,$D$2,Details!$AF:$AF) -> 0 | O11: =SUMIF(Details!$B:$B,$D$2,Details!$AF:$AF) -> 0 | P11: =SUMIF(Details!$B:$B,$D$2,Details!$AF:$AF) -> 0 | Q11: =SUMIF(Details!$B:$B,$D$2,Details!$AF:$AF) -> 0 | ... S11: =SUMIF(Details!$B:$B,$D$2,Details!$AF:$AF) -> 0 | U11: =$C11-SUM(E11:J11) -> 0
A12: CGST | C12: =Details!AG1 -> 0 | E12: 0 | F12: 0 | G12: 0 | H12: 0 | I12: 0 | J12: =SUMIF(Details!$B:$B,$D$2,Details!$AG:$AG) -> 0 | K12: =SUMIF(Details!$B:$B,$D$2,Details!$AG:$AG) -> 0 | L12: =SUMIF(Details!$B:$B,$D$2,Details!$AG:$AG) -> 0 | M12: =SUMIF(Details!$B:$B,$D$2,Details!$AG:$AG) -> 0 | N12: =SUMIF(Details!$B:$B,$D$2,Details!$AG:$AG) -> 0 | O12: =SUMIF(Details!$B:$B,$D$2,Details!$AG:$AG) -> 0 | P12: =SUMIF(Details!$B:$B,$D$2,Details!$AG:$AG) -> 0 | Q12: =SUMIF(Details!$B:$B,$D$2,Details!$AG:$AG) -> 0 | ... S12: =SUMIF(Details!$B:$B,$D$2,Details!$AG:$AG) -> 0 | U12: =$C12-SUM(E12:J12) -> 0
A13: IGST | C13: =Details!AH1 -> 4059451 | E13: 3914102.3 | F13: -3373.1456 | G13: 80802.085 | H13: 11938.591 | I13: 24991.405 | J13: =SUMIF(Details!$B:$B,$D$2,Details!$AH:$AH) -> 30989.757 | K13: =SUMIF(Details!$B:$B,$D$2,Details!$AH:$AH) -> 30989.757 | L13: =SUMIF(Details!$B:$B,$D$2,Details!$AH:$AH) -> 30989.757 | M13: =SUMIF(Details!$B:$B,$D$2,Details!$AH:$AH) -> 30989.757 | N13: =SUMIF(Details!$B:$B,$D$2,Details!$AH:$AH) -> 30989.757 | O13: =SUMIF(Details!$B:$B,$D$2,Details!$AH:$AH) -> 30989.757 | P13: =SUMIF(Details!$B:$B,$D$2,Details!$AH:$AH) -> 30989.757 | Q13: =SUMIF(Details!$B:$B,$D$2,Details!$AH:$AH) -> 30989.757 | ... S13: =SUMIF(Details!$B:$B,$D$2,Details!$AH:$AH) -> 30989.757 | U13: =$C13-SUM(E13:J13) -> 5.5879354e-09
A14: Total GST | C14: =SUM(C11:C13) -> 4059451 | E14: 3914102.3 | F14: -3373.1456 | G14: 80802.085 | H14: 11938.591 | I14: 24991.405 | J14: =SUM(J11:J13) -> 30989.757 | K14: =SUM(K11:K13) -> 30989.757 | L14: =SUM(L11:L13) -> 30989.757 | M14: =SUM(M11:M13) -> 30989.757 | N14: =SUM(N11:N13) -> 30989.757 | O14: =SUM(O11:O13) -> 30989.757 | P14: =SUM(P11:P13) -> 30989.757 | Q14: =SUM(Q11:Q13) -> 30989.757 | ... S14: =SUM(S11:S13) -> 30989.757 | U14: =$C14-SUM(E14:J14) -> 5.5879354e-09
U15: =$C15-SUM(E15:J15) -> 0
A16: Reinsurance Premium: | U16: =$C16-SUM(E16:J16) -> 0
A17: Reinsurance Premium - Obligatory | C17: =Details!AI1 -> 902100.23 | E17: 869800.52 | F17: -749.5879 | G17: 17956.019 | H17: 2653.0202 | I17: 5553.6455 | J17: =SUMIF(Details!$B:$B,$D$2,Details!$AI:$AI) -> 6886.6128 | K17: =SUMIF(Details!$B:$B,$D$2,Details!$AI:$AI) -> 6886.6128 | L17: =SUMIF(Details!$B:$B,$D$2,Details!$AI:$AI) -> 6886.6128 | M17: =SUMIF(Details!$B:$B,$D$2,Details!$AI:$AI) -> 6886.6128 | N17: =SUMIF(Details!$B:$B,$D$2,Details!$AI:$AI) -> 6886.6128 | O17: =SUMIF(Details!$B:$B,$D$2,Details!$AI:$AI) -> 6886.6128 | P17: =SUMIF(Details!$B:$B,$D$2,Details!$AI:$AI) -> 6886.6128 | Q17: =SUMIF(Details!$B:$B,$D$2,Details!$AI:$AI) -> 6886.6128 | ... S17: =SUMIF(Details!$B:$B,$D$2,Details!$AI:$AI) -> 6886.6128 | U17: =$C17-SUM(E17:J17) -> 0
A18: Reinsurance Premium - Quota Share | C18: =Details!AJ1 -> 5074313.8 | E18: 4892627.9 | F18: -4216.432 | G18: 101002.61 | H18: 14923.239 | I18: 31239.256 | J18: =SUMIF(Details!$B:$B,$D$2,Details!$AJ:$AJ) -> 38737.197 | K18: =SUMIF(Details!$B:$B,$D$2,Details!$AJ:$AJ) -> 38737.197 | L18: =SUMIF(Details!$B:$B,$D$2,Details!$AJ:$AJ) -> 38737.197 | M18: =SUMIF(Details!$B:$B,$D$2,Details!$AJ:$AJ) -> 38737.197 | N18: =SUMIF(Details!$B:$B,$D$2,Details!$AJ:$AJ) -> 38737.197 | O18: =SUMIF(Details!$B:$B,$D$2,Details!$AJ:$AJ) -> 38737.197 | P18: =SUMIF(Details!$B:$B,$D$2,Details!$AJ:$AJ) -> 38737.197 | Q18: =SUMIF(Details!$B:$B,$D$2,Details!$AJ:$AJ) -> 38737.197 | ... S18: =SUMIF(Details!$B:$B,$D$2,Details!$AJ:$AJ) -> 38737.197 | U18: =$C18-SUM(E18:J18) -> 0
U19: =$C19-SUM(E19:J19) -> 0
A20: Commission on Reinsurance Premium: | U20: =$C20-SUM(E20:J20) -> 0
A21: Reinsurance Commission - Obligatory | C21: =ROUND(C17*10%,0) -> 90210 | E21: 86980 | F21: -75 | G21: 1796 | H21: 265 | I21: 555 | J21: =ROUND(J17*10%,0) -> 689 | K21: =ROUND(K17*10%,0) -> 689 | L21: =ROUND(L17*10%,0) -> 689 | M21: =ROUND(M17*10%,0) -> 689 | N21: =ROUND(N17*10%,0) -> 689 | O21: =ROUND(O17*10%,0) -> 689 | P21: =ROUND(P17*10%,0) -> 689 | Q21: =ROUND(Q17*10%,0) -> 689 | ... S21: =ROUND(S17*10%,0) -> 689 | U21: =$C21-SUM(E21:J21) -> 0
A22: Reinsurance Commission - Quota Share | C22: =ROUND(C18*50%,0) -> 2537157 | E22: 2446314 | F22: -2108 | G22: 50501 | H22: 7462 | I22: 15620 | J22: =ROUND(J18*50%,0) -> 19369 | K22: =ROUND(K18*50%,0) -> 19369 | L22: =ROUND(L18*50%,0) -> 19369 | M22: =ROUND(M18*50%,0) -> 19369 | N22: =ROUND(N18*50%,0) -> 19369 | O22: =ROUND(O18*50%,0) -> 19369 | P22: =ROUND(P18*50%,0) -> 19369 | Q22: =ROUND(Q18*50%,0) -> 19369 | ... S22: =ROUND(S18*50%,0) -> 19369 | U22: =$C22-SUM(E22:J22) -> -1
E23: 0 | F23: 0 | G23: 0 | H23: 0 | I23: 0 | J23: =ROUND(J19*10%,0) -> 0 | K23: =ROUND(K19*10%,0) -> 0 | L23: =ROUND(L19*10%,0) -> 0 | M23: =ROUND(M19*10%,0) -> 0 | N23: =ROUND(N19*10%,0) -> 0 | O23: =ROUND(O19*10%,0) -> 0 | P23: =ROUND(P19*10%,0) -> 0 | Q23: =ROUND(Q19*10%,0) -> 0 | ... S23: =ROUND(S19*10%,0) -> 0 | U23: =$C23-SUM(E23:J23) -> 0
A24: GEP | C24: =Details!AK1 -> 11034160 | E24: 1782648.8 | F24: 1843675.8 | G24: 1840535.2 | H24: 1898203 | I24: 1918898.3 | J24: =$C24-SUM($D24:I24) -> 1750199.2 | K24: =$C24-SUM($D24:J24) -> 0 | L24: =$C24-SUM($D24:K24) -> 0 | M24: =$C24-SUM($D24:L24) -> 0 | N24: =$C24-SUM($D24:M24) -> 0 | O24: =$C24-SUM($D24:N24) -> 0 | P24: =$C24-SUM($D24:O24) -> 0 | Q24: =$C24-SUM($D24:P24) -> 0 | ... S24: =$C24-SUM($D24:R24) -> 0 | U24: =$C24-SUM(E24:J24) -> 0
U25: =$C25-SUM(E25:J25) -> 0
A26: NEP | C26: =Details!AL1 -> 8110107.8 | E26: 1310246.9 | F26: 1355101.7 | G26: 1352793.3 | H26: 1395179.2 | I26: 1410390.2 | J26: =$C26-SUM($D26:I26) -> 1286396.4 | K26: =$C26-SUM($D26:J26) -> 0 | L26: =$C26-SUM($D26:K26) -> 0 | M26: =$C26-SUM($D26:L26) -> 0 | N26: =$C26-SUM($D26:M26) -> 0 | O26: =$C26-SUM($D26:N26) -> 0 | P26: =$C26-SUM($D26:O26) -> 0 | Q26: =$C26-SUM($D26:P26) -> 0 | ... S26: =$C26-SUM($D26:R26) -> 0 | U26: =$C26-SUM(E26:J26) -> 0
U27: =$C27-SUM(E27:J27) -> 0
A28: NURR | C28: =C8-C17-C26-C18 -> 8465983.8 | E28: 14672338 | F28: -1368875.4 | G28: -1022851.5 | H28: -1346429.9 | I28: -1308342 | J28: =J8-J17-J26-J18 -> -1159854.9 | K28: =K8-K17-K26-K18 -> 126541.51 | L28: =L8-L17-L26-L18 -> 126541.51 | M28: =M8-M17-M26-M18 -> 126541.51 | N28: =N8-N17-N26-N18 -> 126541.51 | O28: =O8-O17-O26-O18 -> 126541.51 | P28: =P8-P17-P26-P18 -> 126541.51 | Q28: =Q8-Q17-Q26-Q18 -> 126541.51 | ... S28: =S8-S17-S26-S18 -> 126541.51 | U28: =$C28-SUM(E28:J28) -> 4.2840838e-08
U29: =$C29-SUM(E29:J29) -> 0
A30: Total No of COI/No of Plan Sold | C30: =Details!X1 -> 759 | E30: 706 | F30: 0 | G30: 25 | H30: 5 | I30: 10 | J30: =SUMIF(Details!$B:$B,$D$2,Details!$X:$X) -> 13 | K30: =SUMIF(Details!$B:$B,$D$2,Details!$X:$X) -> 13 | L30: =SUMIF(Details!$B:$B,$D$2,Details!$X:$X) -> 13 | M30: =SUMIF(Details!$B:$B,$D$2,Details!$X:$X) -> 13 | N30: =SUMIF(Details!$B:$B,$D$2,Details!$X:$X) -> 13 | O30: =SUMIF(Details!$B:$B,$D$2,Details!$X:$X) -> 13 | P30: =SUMIF(Details!$B:$B,$D$2,Details!$X:$X) -> 13 | Q30: =SUMIF(Details!$B:$B,$D$2,Details!$X:$X) -> 13 | ... S30: =SUMIF(Details!$B:$B,$D$2,Details!$X:$X) -> 13 | U30: =$C30-SUM(E30:J30) -> 0
U31: =$C31-SUM(E31:J31) -> 0
A32: Total No of Life Cover | C32: =Details!AD1 -> 3167 | E32: 2963 | F32: 19 | G32: 86 | H32: 18 | I32: 36 | J32: =SUMIF(Details!$B:$B,$D$2,Details!$AD:$AD) -> 45 | K32: =SUMIF(Details!$B:$B,$D$2,Details!$AD:$AD) -> 45 | L32: =SUMIF(Details!$B:$B,$D$2,Details!$AD:$AD) -> 45 | M32: =SUMIF(Details!$B:$B,$D$2,Details!$AD:$AD) -> 45 | N32: =SUMIF(Details!$B:$B,$D$2,Details!$AD:$AD) -> 45 | O32: =SUMIF(Details!$B:$B,$D$2,Details!$AD:$AD) -> 45 | P32: =SUMIF(Details!$B:$B,$D$2,Details!$AD:$AD) -> 45 | Q32: =SUMIF(Details!$B:$B,$D$2,Details!$AD:$AD) -> 45 | ... S32: =SUMIF(Details!$B:$B,$D$2,Details!$AD:$AD) -> 45 | U32: =$C32-SUM(E32:J32) -> 0
U33: =$C33-SUM(E33:J33) -> 0
A34: Prudent Insurance Brokerage - 2.38% | U34: =$C34-SUM(E34:J34) -> 0
A35: Commission | C35: =2.38%*C8 -> 536749.63 | E35: 517531.31 | F35: -446.0048 | G35: 10683.831 | H35: 1578.547 | I35: 3304.4191 | J35: =$C35-SUM($D35:I35) -> 4097.5346 | K35: =$C35-SUM($D35:J35) -> 0 | L35: =$C35-SUM($D35:K35) -> 0 | M35: =$C35-SUM($D35:L35) -> 0 | N35: =$C35-SUM($D35:M35) -> 0 | O35: =$C35-SUM($D35:N35) -> 0 | P35: =$C35-SUM($D35:O35) -> 0 | Q35: =$C35-SUM($D35:P35) -> 0 | ... S35: =$C35-SUM($D35:R35) -> 0 | U35: =$C35-SUM(E35:J35) -> 0
U36: =$C36-SUM(E36:J36) -> 0
A37: Total SA | C37: =Details!W1 -> 300500000 | E37: 281100000 | F37: 0 | G37: 10100000 | H37: 1700000 | I37: 3400000 | J37: =$C37-SUM($D37:I37) -> 4200000 | K37: =$C37-SUM($D37:J37) -> 0 | L37: =$C37-SUM($D37:K37) -> 0 | M37: =$C37-SUM($D37:L37) -> 0 | N37: =$C37-SUM($D37:M37) -> 0 | O37: =$C37-SUM($D37:N37) -> 0 | P37: =$C37-SUM($D37:O37) -> 0 | Q37: =$C37-SUM($D37:P37) -> 0 | ... S37: =$C37-SUM($D37:R37) -> 0 | U37: =$C37-SUM(E37:J37) -> 0
U38: =$C38-SUM(E38:J38) -> 0
A39: Master Policy No (Passenger) | C39: =Details!C3 -> GMC023220100CALDERYS
A40: Period | C40: : 01-09-2025 to 31-08-2026
A41: Proposer Name | C41: =Details!D3 -> CALDERYS INDIA REFRACTORIES LIMITED
A43: Name on Premium Summary | B43: CALDERYS-GMC-GMC023220100CALDERYS
...

Sheet Details
H1: 652569 | V1: =ROUND(SUM(V3:V1048576),0) -> 1261100000 | W1: =ROUND(SUM(W3:W1048576),0) -> 300500000 | X1: =ROUND(SUM(X3:X1048576),0) -> 759 | Z1: 46081 | AB1: Total | AC1: =ROUND(SUM(AC3:AC1048576),0) -> 26611957 | AD1: =ROUND(SUM(AD3:AD1048576),0) -> 3167 | AE1: =SUM(AE3:AE1048576) -> 22552506 | AF1: =SUM(AF3:AF1048576) -> 0 | AG1: =SUM(AG3:AG1048576) -> 0 | AH1: =SUM(AH3:AH1048576) -> 4059451 | AI1: =SUM(AI3:AI1048576) -> 902100.23 | AJ1: =SUM(AJ3:AJ1048576) -> 5074313.8 | AK1: =SUM(AK3:AK1048576) -> 11034160 | AL1: =SUM(AL3:AL1048576) -> 8110107.8 | AM1: =SUM(AM3:AM1048576) -> 8465983.8 | AO1: =ROUND(SUM(AO3:AO1048576),0) -> 22552506
A2: Status | B2: Acct. Month | C2: Master Policy No | D2: Master Policy Holder Name | E2: Master Policy Risk Start Date | F2: Master Policy Risk End Date | G2: Name | H2: Emp ID | I2: DOB | J2: UHID | K2: Policy Risk Start Date | L2: Ri Obligatory | M2: RI Quota | N2: Risk Start Date | O2: Risk End Date | P2: Last Working Day | Q2: Reversal Date | R2: Age | S2: Age Band | T2: Gender | U2: Relationship | V2: Sum Insured | W2: Reporting Sum Insured | X2: No of Policies | Y2: Risk Days | Z2: Base Date | AA2: Used | AB2: State | AC2: Gross Premium | AD2: No of Person Cover Per Day | AE2: GWP | AF2: SGST/UGST | AG2: CGST | AH2: IGST | AI2: Reinsurance Premium -Obligatory | AJ2: Reinsurance Premium -Quota | AK2: GEP | AL2: NEP | AM2: NURR | AN2: Unexpired Premium Date | AO2: Unexpired Premium | AP2: Claim Status
A3: Valid | B3: 202509 | C3: GMC023220100CALDERYS | D3: CALDERYS INDIA REFRACTORIES LIMITED | E3: 45901 | F3: 46265 | G3: Kanchana Chakraborty | H3: 11350 | I3: 24166 | J3: ACK.4A9F3020250658.1 | K3: =N3 -> 45901 | L3: =IF(K3>=DATE(2022,4,1),4%,5%) -> 0.04 | M3: 0.225 | N3: 45901 | O3: 46265 | R3: 59 | S3: =VLOOKUP(R3,SA!$B$3:$C$11,2,1) -> 56-65 | T3: Female | U3: Spouse | V3: 600000 | W3: =IF(U3="self",V3,0) -> 0 | X3: =IF(U3="self",1,0) -> 0 | Y3: =O3-N3+1 -> 365 | Z3: =$Z$1 -> 46081 | AA3: =IF(MIN((Z3-N3)+1,Y3)<0,0,MIN((Z3-N3)+1,Y3)) -> 181 | AB3: Maharashtra | AC3: =AE3+AF3+AG3+AH3 -> 14410.797 | AD3: 1 | AE3: =INDEX(SA!$C$2:$G$11,MATCH(Details!S3,SA!$C$2:$C$11,0),MATCH(Details!V3,SA!$C$2:$G$2,0))*Y3/(F3-E3+1) -> 12212.54 | AF3: =IF(AB3="Karnataka",AE3*9%,0) -> 0 | AG3: =IF(AB3="Karnataka",AE3*9%,0) -> 0 | AH3: =IF(AF3+AG3>0,0,AE3*18%) -> 2198.2572 | AI3: =AE3*L3 -> 488.5016 | AJ3: =$AE3*M3 -> 2747.8215 | AK3: =(AE3)*AA3/Y3 -> 6056.0815 | AL3: =AK3*(1-L3-M3) -> 4451.2199 | AM3: =AE3-AI3-AL3-AJ3 -> 4524.997 | AN3: =Z3-366 -> 45715 | AO3: =IF(AND(O3>Z3,N3>AN3),AE3,0) -> 12212.54
A4: Valid | B4: 202509 | C4: GMC023220100CALDERYS | D4: CALDERYS INDIA REFRACTORIES LIMITED | E4: 45901 | F4: 46265 | G4: Indra Nath Chakraborty | H4: 11350 | I4: 20846 | J4: ACK.4A9F3020250658.2 | K4: =N4 -> 45901 | L4: =IF(K4>=DATE(2022,4,1),4%,5%) -> 0.04 | M4: 0.225 | N4: 45901 | O4: 46265 | R4: 68 | S4: =VLOOKUP(R4,SA!$B$3:$C$11,2,1) -> 66-70 | T4: Male | U4: Self | V4: 600000 | W4: =IF(U4="self",V4,0) -> 600000 | X4: =IF(U4="self",1,0) -> 1 | Y4: =O4-N4+1 -> 365 | Z4: =$Z$1 -> 46081 | AA4: =IF(MIN((Z4-N4)+1,Y4)<0,0,MIN((Z4-N4)+1,Y4)) -> 181 | AB4: Maharashtra | AC4: =AE4+AF4+AG4+AH4 -> 20584.357 | AD4: 1 | AE4: =INDEX(SA!$C$2:$G$11,MATCH(Details!S4,SA!$C$2:$C$11,0),MATCH(Details!V4,SA!$C$2:$G$2,0))*Y4/(F4-E4+1) -> 17444.37 | AF4: =IF(AB4="Karnataka",AE4*9%,0) -> 0 | AG4: =IF(AB4="Karnataka",AE4*9%,0) -> 0 | AH4: =IF(AF4+AG4>0,0,AE4*18%) -> 3139.9866 | AI4: =AE4*L4 -> 697.7748 | AJ4: =$AE4*M4 -> 3924.9832 | AK4: =(AE4)*AA4/Y4 -> 8650.4958 | AL4: =AK4*(1-L4-M4) -> 6358.1144 | AM4: =AE4-AI4-AL4-AJ4 -> 6463.4975 | AN4: =Z4-366 -> 45715 | AO4: =IF(AND(O4>Z4,N4>AN4),AE4,0) -> 17444.37
A5: Valid | B5: 202509 | C5: GMC023220100CALDERYS | D5: CALDERYS INDIA REFRACTORIES LIMITED | E5: 45901 | F5: 46265 | G5: Manisha Bajpai | H5: 41022 | I5: 27546 | J5: ACK.4A9F3020250661.1 | K5: =N5 -> 45901 | L5: =IF(K5>=DATE(2022,4,1),4%,5%) -> 0.04 | M5: 0.225 | N5: 45901 | O5: 46265 | R5: 50 | S5: =VLOOKUP(R5,SA!$B$3:$C$11,2,1) -> 46-55 | T5: Female | U5: Spouse | V5: 300000 | W5: =IF(U5="self",V5,0) -> 0 | X5: =IF(U5="self",1,0) -> 0 | Y5: =O5-N5+1 -> 365 | Z5: =$Z$1 -> 46081 | AA5: =IF(MIN((Z5-N5)+1,Y5)<0,0,MIN((Z5-N5)+1,Y5)) -> 181 | AB5: Maharashtra | AC5: =AE5+AF5+AG5+AH5 -> 7373.466 | AD5: 1 | AE5: =INDEX(SA!$C$2:$G$11,MATCH(Details!S5,SA!$C$2:$C$11,0),MATCH(Details!V5,SA!$C$2:$G$2,0))*Y5/(F5-E5+1) -> 6248.7 | AF5: =IF(AB5="Karnataka",AE5*9%,0) -> 0 | AG5: =IF(AB5="Karnataka",AE5*9%,0) -> 0 | AH5: =IF(AF5+AG5>0,0,AE5*18%) -> 1124.766 | AI5: =AE5*L5 -> 249.948 | AJ5: =$AE5*M5 -> 1405.9575 | AK5: =(AE5)*AA5/Y5 -> 3098.6704 | AL5: =AK5*(1-L5-M5) -> 2277.5228 | AM5: =AE5-AI5-AL5-AJ5 -> 2315.2717 | AN5: =Z5-366 -> 45715 | AO5: =IF(AND(O5>Z5,N5>AN5),AE5,0) -> 6248.7
A6: Valid | B6: 202509 | C6: GMC023220100CALDERYS | D6: CALDERYS INDIA REFRACTORIES LIMITED | E6: 45901 | F6: 46265 | G6: Devi Prasad Bajpai | H6: 41022 | I6: 16560 | J6: ACK.4A9F3020250661.2 | K6: =N6 -> 45901 | L6: =IF(K6>=DATE(2022,4,1),4%,5%) -> 0.04 | M6: 0.225 | N6: 45901 | O6: 46265 | R6: 80 | S6: =VLOOKUP(R6,SA!$B$3:$C$11,2,1) -> 76-80 | T6: Male | U6: Father | V6: 300000 | W6: =IF(U6="self",V6,0) -> 0 | X6: =IF(U6="self",1,0) -> 0 | Y6: =O6-N6+1 -> 365 | Z6: =$Z$1 -> 46081 | AA6: =IF(MIN((Z6-N6)+1,Y6)<0,0,MIN((Z6-N6)+1,Y6)) -> 181 | AB6: Maharashtra | AC6: =AE6+AF6+AG6+AH6 -> 24649.079 | AD6: 1 | AE6: =INDEX(SA!$C$2:$G$11,MATCH(Details!S6,SA!$C$2:$C$11,0),MATCH(Details!V6,SA!$C$2:$G$2,0))*Y6/(F6-E6+1) -> 20889.05 | AF6: =IF(AB6="Karnataka",AE6*9%,0) -> 0 | AG6: =IF(AB6="Karnataka",AE6*9%,0) -> 0 | AH6: =IF(AF6+AG6>0,0,AE6*18%) -> 3760.029 | AI6: =AE6*L6 -> 835.562 | AJ6: =$AE6*M6 -> 4700.0363 | AK6: =(AE6)*AA6/Y6 -> 10358.68 | AL6: =AK6*(1-L6-M6) -> 7613.6295 | AM6: =AE6-AI6-AL6-AJ6 -> 7739.8223 | AN6: =Z6-366 -> 45715 | AO6: =IF(AND(O6>Z6,N6>AN6),AE6,0) -> 20889.05
A7: Valid | B7: 202509 | C7: GMC023220100CALDERYS | D7: CALDERYS INDIA REFRACTORIES LIMITED | E7: 45901 | F7: 46265 | G7: Abishek Bajpai | H7: 41022 | I7: 38528 | J7: ACK.4A9F3020250661.3 | K7: =N7 -> 45901 | L7: =IF(K7>=DATE(2022,4,1),4%,5%) -> 0.04 | M7: 0.225 | N7: 45901 | O7: 46265 | R7: 20 | S7: =VLOOKUP(R7,SA!$B$3:$C$11,2,1) -> 0-25 | T7: Male | U7: Son | V7: 300000 | W7: =IF(U7="self",V7,0) -> 0 | X7: =IF(U7="self",1,0) -> 0 | Y7: =O7-N7+1 -> 365 | Z7: =$Z$1 -> 46081 | AA7: =IF(MIN((Z7-N7)+1,Y7)<0,0,MIN((Z7-N7)+1,Y7)) -> 181 | AB7: Maharashtra | AC7: =AE7+AF7+AG7+AH7 -> 3690.3792 | AD7: 1 | AE7: =INDEX(SA!$C$2:$G$11,MATCH(Details!S7,SA!$C$2:$C$11,0),MATCH(Details!V7,SA!$C$2:$G$2,0))*Y7/(F7-E7+1) -> 3127.44 | AF7: =IF(AB7="Karnataka",AE7*9%,0) -> 0 | AG7: =IF(AB7="Karnataka",AE7*9%,0) -> 0 | AH7: =IF(AF7+AG7>0,0,AE7*18%) -> 562.9392 | AI7: =AE7*L7 -> 125.0976 | AJ7: =$AE7*M7 -> 703.674 | AK7: =(AE7)*AA7/Y7 -> 1550.8675 | AL7: =AK7*(1-L7-M7) -> 1139.8876 | AM7: =AE7-AI7-AL7-AJ7 -> 1158.7808 | AN7: =Z7-366 -> 45715 | AO7: =IF(AND(O7>Z7,N7>AN7),AE7,0) -> 3127.44
A8: Valid | B8: 202509 | C8: GMC023220100CALDERYS | D8: CALDERYS INDIA REFRACTORIES LIMITED | E8: 45901 | F8: 46265 | G8: Priya Bajpai | H8: 41022 | I8: 36381 | J8: ACK.4A9F3020250661.4 | K8: =N8 -> 45901 | L8: =IF(K8>=DATE(2022,4,1),4%,5%) -> 0.04 | M8: 0.225 | N8: 45901 | O8: 46265 | R8: 26 | S8: =VLOOKUP(R8,SA!$B$3:$C$11,2,1) -> 26-35 | T8: Female | U8: Daughter | V8: 300000 | W8: =IF(U8="self",V8,0) -> 0 | X8: =IF(U8="self",1,0) -> 0 | Y8: =O8-N8+1 -> 365 | Z8: =$Z$1 -> 46081 | AA8: =IF(MIN((Z8-N8)+1,Y8)<0,0,MIN((Z8-N8)+1,Y8)) -> 181 | AB8: Maharashtra | AC8: =AE8+AF8+AG8+AH8 -> 4124.4658 | AD8: 1 | AE8: =INDEX(SA!$C$2:$G$11,MATCH(Details!S8,SA!$C$2:$C$11,0),MATCH(Details!V8,SA!$C$2:$G$2,0))*Y8/(F8-E8+1) -> 3495.31 | AF8: =IF(AB8="Karnataka",AE8*9%,0) -> 0 | AG8: =IF(AB8="Karnataka",AE8*9%,0) -> 0 | AH8: =IF(AF8+AG8>0,0,AE8*18%) -> 629.1558 | AI8: =AE8*L8 -> 139.8124 | AJ8: =$AE8*M8 -> 786.44475 | AK8: =(AE8)*AA8/Y8 -> 1733.2907 | AL8: =AK8*(1-L8-M8) -> 1273.9687 | AM8: =AE8-AI8-AL8-AJ8 -> 1295.0842 | AN8: =Z8-366 -> 45715 | AO8: =IF(AND(O8>Z8,N8>AN8),AE8,0) -> 3495.31
A9: Valid | B9: 202509 | C9: GMC023220100CALDERYS | D9: CALDERYS INDIA REFRACTORIES LIMITED | E9: 45901 | F9: 46265 | G9: Ravi Shanker Bajpai | H9: 41022 | I9: 25660 | J9: ACK.4A9F3020250661.5 | K9: =N9 -> 45901 | L9: =IF(K9>=DATE(2022,4,1),4%,5%) -> 0.04 | M9: 0.225 | N9: 45901 | O9: 46265 | R9: 55 | S9: =VLOOKUP(R9,SA!$B$3:$C$11,2,1) -> 46-55 | T9: Male | U9: Self | V9: 300000 | W9: =IF(U9="self",V9,0) -> 300000 | X9: =IF(U9="self",1,0) -> 1 | Y9: =O9-N9+1 -> 365 | Z9: =$Z$1 -> 46081 | AA9: =IF(MIN((Z9-N9)+1,Y9)<0,0,MIN((Z9-N9)+1,Y9)) -> 181 | AB9: Maharashtra | AC9: =AE9+AF9+AG9+AH9 -> 7373.466 | AD9: 1 | AE9: =INDEX(SA!$C$2:$G$11,MATCH(Details!S9,SA!$C$2:$C$11,0),MATCH(Details!V9,SA!$C$2:$G$2,0))*Y9/(F9-E9+1) -> 6248.7 | AF9: =IF(AB9="Karnataka",AE9*9%,0) -> 0 | AG9: =IF(AB9="Karnataka",AE9*9%,0) -> 0 | AH9: =IF(AF9+AG9>0,0,AE9*18%) -> 1124.766 | AI9: =AE9*L9 -> 249.948 | AJ9: =$AE9*M9 -> 1405.9575 | AK9: =(AE9)*AA9/Y9 -> 3098.6704 | AL9: =AK9*(1-L9-M9) -> 2277.5228 | AM9: =AE9-AI9-AL9-AJ9 -> 2315.2717 | AN9: =Z9-366 -> 45715 | AO9: =IF(AND(O9>Z9,N9>AN9),AE9,0) -> 6248.7
A10: Valid | B10: 202509 | C10: GMC023220100CALDERYS | D10: CALDERYS INDIA REFRACTORIES LIMITED | E10: 45901 | F10: 46265 | G10: Shiv Prasad Tripathi | H10: 41023 | I10: 18737 | J10: ACK.4A9F3020250078.1 | K10: =N10 -> 45901 | L10: =IF(K10>=DATE(2022,4,1),4%,5%) -> 0.04 | M10: 0.225 | N10: 45901 | O10: 46265 | R10: 74 | S10: =VLOOKUP(R10,SA!$B$3:$C$11,2,1) -> 71-75 | T10: Male | U10: Father | V10: 400000 | W10: =IF(U10="self",V10,0) -> 0 | X10: =IF(U10="self",1,0) -> 0 | Y10: =O10-N10+1 -> 365 | Z10: =$Z$1 -> 46081 | AA10: =IF(MIN((Z10-N10)+1,Y10)<0,0,MIN((Z10-N10)+1,Y10)) -> 181 | AB10: Maharashtra | AC10: =AE10+AF10+AG10+AH10 -> 21578.035 | AD10: 1 | AE10: =INDEX(SA!$C$2:$G$11,MATCH(Details!S10,SA!$C$2:$C$11,0),MATCH(Details!V10,SA!$C$2:$G$2,0))*Y10/(F10-E10+1) -> 18286.47 | AF10: =IF(AB10="Karnataka",AE10*9%,0) -> 0 | AG10: =IF(AB10="Karnataka",AE10*9%,0) -> 0 | AH10: =IF(AF10+AG10>0,0,AE10*18%) -> 3291.5646 | AI10: =AE10*L10 -> 731.4588 | AJ10: =$AE10*M10 -> 4114.4558 | AK10: =(AE10)*AA10/Y10 -> 9068.0851 | AL10: =AK10*(1-L10-M10) -> 6665.0426 | AM10: =AE10-AI10-AL10-AJ10 -> 6775.5129 | AN10: =Z10-366 -> 45715 | AO10: =IF(AND(O10>Z10,N10>AN10),AE10,0) -> 18286.47
A11: Valid | B11: 202509 | C11: GMC023220100CALDERYS | D11: CALDERYS INDIA REFRACTORIES LIMITED | E11: 45901 | F11: 46265 | G11: Anita Tripathi | H11: 41023 | I11: 28732 | J11: ACK.4A9F3020250078.2 | K11: =N11 -> 45901 | L11: =IF(K11>=DATE(2022,4,1),4%,5%) -> 0.04 | M11: 0.225 | N11: 45901 | O11: 46265 | R11: 47 | S11: =VLOOKUP(R11,SA!$B$3:$C$11,2,1) -> 46-55 | T11: Female | U11: Spouse | V11: 400000 | W11: =IF(U11="self",V11,0) -> 0 | X11: =IF(U11="self",1,0) -> 0 | Y11: =O11-N11+1 -> 365 | Z11: =$Z$1 -> 46081 | AA11: =IF(MIN((Z11-N11)+1,Y11)<0,0,MIN((Z11-N11)+1,Y11)) -> 181 | AB11: Maharashtra | AC11: =AE11+AF11+AG11+AH11 -> 8108.2166 | AD11: 1 | AE11: =INDEX(SA!$C$2:$G$11,MATCH(Details!S11,SA!$C$2:$C$11,0),MATCH(Details!V11,SA!$C$2:$G$2,0))*Y11/(F11-E11+1) -> 6871.37 | AF11: =IF(AB11="Karnataka",AE11*9%,0) -> 0 | AG11: =IF(AB11="Karnataka",AE11*9%,0) -> 0 | AH11: =IF(AF11+AG11>0,0,AE11*18%) -> 1236.8466 | AI11: =AE11*L11 -> 274.8548 | AJ11: =$AE11*M11 -> 1546.0583 | AK11: =(AE11)*AA11/Y11 -> 3407.4465 | AL11: =AK11*(1-L11-M11) -> 2504.4732 | AM11: =AE11-AI11-AL11-AJ11 -> 2545.9838 | AN11: =Z11-366 -> 45715 | AO11: =IF(AND(O11>Z11,N11>AN11),AE11,0) -> 6871.37
A12: Valid | B12: 202509 | C12: GMC023220100CALDERYS | D12: CALDERYS INDIA REFRACTORIES LIMITED | E12: 45901 | F12: 46265 | G12: Shakun Tripathi | H12: 41023 | I12: 19207 | J12: ACK.4A9F3020250078.3 | K12: =N12 -> 45901 | L12: =IF(K12>=DATE(2022,4,1),4%,5%) -> 0.04 | M12: 0.225 | N12: 45901 | O12: 46265 | R12: 73 | S12: =VLOOKUP(R12,SA!$B$3:$C$11,2,1) -> 71-75 | T12: Female | U12: Mother | V12: 400000 | W12: =IF(U12="self",V12,0) -> 0 | X12: =IF(U12="self",1,0) -> 0 | Y12: =O12-N12+1 -> 365 | Z12: =$Z$1 -> 46081 | AA12: =IF(MIN((Z12-N12)+1,Y12)<0,0,MIN((Z12-N12)+1,Y12)) -> 181 | AB12: Maharashtra | AC12: =AE12+AF12+AG12+AH12 -> 21578.035 | AD12: 1 | AE12: =INDEX(SA!$C$2:$G$11,MATCH(Details!S12,SA!$C$2:$C$11,0),MATCH(Details!V12,SA!$C$2:$G$2,0))*Y12/(F12-E12+1) -> 18286.47 | AF12: =IF(AB12="Karnataka",AE12*9%,0) -> 0 | AG12: =IF(AB12="Karnataka",AE12*9%,0) -> 0 | AH12: =IF(AF12+AG12>0,0,AE12*18%) -> 3291.5646 | AI12: =AE12*L12 -> 731.4588 | AJ12: =$AE12*M12 -> 4114.4558 | AK12: =(AE12)*AA12/Y12 -> 9068.0851 | AL12: =AK12*(1-L12-M12) -> 6665.0426 | AM12: =AE12-AI12-AL12-AJ12 -> 6775.5129 | AN12: =Z12-366 -> 45715 | AO12: =IF(AND(O12>Z12,N12>AN12),AE12,0) -> 18286.47
A13: Valid | B13: 202509 | C13: GMC023220100CALDERYS | D13: CALDERYS INDIA REFRACTORIES LIMITED | E13: 45901 | F13: 46265 | G13: Kedar Prasad | H13: 41023 | I13: 27207 | J13: ACK.4A9F3020250078.4 | K13: =N13 -> 45901 | L13: =IF(K13>=DATE(2022,4,1),4%,5%) -> 0.04 | M13: 0.225 | N13: 45901 | O13: 46265 | R13: 51 | S13: =VLOOKUP(R13,SA!$B$3:$C$11,2,1) -> 46-55 | T13: Male | U13: Self | V13: 400000 | W13: =IF(U13="self",V13,0) -> 400000 | X13: =IF(U13="self",1,0) -> 1 | Y13: =O13-N13+1 -> 365 | Z13: =$Z$1 -> 46081 | AA13: =IF(MIN((Z13-N13)+1,Y13)<0,0,MIN((Z13-N13)+1,Y13)) -> 181 | AB13: Maharashtra | AC13: =AE13+AF13+AG13+AH13 -> 8108.2166 | AD13: 1 | AE13: =INDEX(SA!$C$2:$G$11,MATCH(Details!S13,SA!$C$2:$C$11,0),MATCH(Details!V13,SA!$C$2:$G$2,0))*Y13/(F13-E13+1) -> 6871.37 | AF13: =IF(AB13="Karnataka",AE13*9%,0) -> 0 | AG13: =IF(AB13="Karnataka",AE13*9%,0) -> 0 | AH13: =IF(AF13+AG13>0,0,AE13*18%) -> 1236.8466 | AI13: =AE13*L13 -> 274.8548 | AJ13: =$AE13*M13 -> 1546.0583 | AK13: =(AE13)*AA13/Y13 -> 3407.4465 | AL13: =AK13*(1-L13-M13) -> 2504.4732 | AM13: =AE13-AI13-AL13-AJ13 -> 2545.9838 | AN13: =Z13-366 -> 45715 | AO13: =IF(AND(O13>Z13,N13>AN13),AE13,0) -> 6871.37
A14: Valid | B14: 202509 | C14: GMC023220100CALDERYS | D14: CALDERYS INDIA REFRACTORIES LIMITED | E14: 45901 | F14: 46265 | G14: Prabhakar Singh | H14: 41024 | I14: 32319 | J14: ACK.4A9F3020250659.1 | K14: =N14 -> 45901 | L14: =IF(K14>=DATE(2022,4,1),4%,5%) -> 0.04 | M14: 0.225 | N14: 45901 | O14: 46265 | R14: 37 | S14: =VLOOKUP(R14,SA!$B$3:$C$11,2,1) -> 36-45 | T14: Male | U14: Son | V14: 300000 | W14: =IF(U14="self",V14,0) -> 0 | X14: =IF(U14="self",1,0) -> 0 | Y14: =O14-N14+1 -> 365 | Z14: =$Z$1 -> 46081 | AA14: =IF(MIN((Z14-N14)+1,Y14)<0,0,MIN((Z14-N14)+1,Y14)) -> 181 | AB14: Maharashtra | AC14: =AE14+AF14+AG14+AH14 -> 5119.5716 | AD14: 1 | AE14: =INDEX(SA!$C$2:$G$11,MATCH(Details!S14,SA!$C$2:$C$11,0),MATCH(Details!V14,SA!$C$2:$G$2,0))*Y14/(F14-E14+1) -> 4338.62 | AF14: =IF(AB14="Karnataka",AE14*9%,0) -> 0 | AG14: =IF(AB14="Karnataka",AE14*9%,0) -> 0 | AH14: =IF(AF14+AG14>0,0,AE14*18%) -> 780.9516 | AI14: =AE14*L14 -> 173.5448 | AJ14: =$AE14*M14 -> 976.1895 | AK14: =(AE14)*AA14/Y14 -> 2151.4801 | AL14: =AK14*(1-L14-M14) -> 1581.3378 | AM14: =AE14-AI14-AL14-AJ14 -> 1607.5479 | AN14: =Z14-366 -> 45715 | AO14: =IF(AND(O14>Z14,N14>AN14),AE14,0) -> 4338.62
... A2876: Valid | B2876: 202509 | C2876: GMC023220100CALDERYS | D2876: CALDERYS INDIA REFRACTORIES LIMITED | E2876: 45901 | F2876: 46265 | G2876: Devraj Parauha | H2876: 45017 | I2876: 35664 | J2876: ACK.4A9F3020250698.2 | K2876: =N2876 -> 45901 | L2876: =IF(K2876>=DATE(2022,4,1),4%,5%) -> 0.04 | M2876: 0.225 | N2876: 45901 | O2876: 46265 | R2876: 28 | S2876: =VLOOKUP(R2876,SA!$B$3:$C$11,2,1) -> 26-35 | T2876: Male | U2876: Self | V2876: 300000 | W2876: =IF(U2876="self",V2876,0) -> 300000 | X2876: =IF(U2876="self",1,0) -> 1 | Y2876: =O2876-N2876+1 -> 365 | Z2876: =$Z$1 -> 46081 | AA2876: =IF(MIN((Z2876-N2876)+1,Y2876)<0,0,MIN((Z2876-N2876)+1,Y2876)) -> 181 | AB2876: Maharashtra | AC2876: =AE2876+AF2876+AG2876+AH2876 -> 4124.4658 | AD2876: 1 | AE2876: =INDEX(SA!$C$2:$G$11,MATCH(Details!S2876,SA!$C$2:$C$11,0),MATCH(Details!V2876,SA!$C$2:$G$2,0))*Y2876/(F2876-E2876+1) -> 3495.31 | AF2876: =IF(AB2876="Karnataka",AE2876*9%,0) -> 0 | AG2876: =IF(AB2876="Karnataka",AE2876*9%,0) -> 0 | AH2876: =IF(AF2876+AG2876>0,0,AE2876*18%) -> 629.1558 | AI2876: =AE2876*L2876 -> 139.8124 | AJ2876: =$AE2876*M2876 -> 786.44475 | AK2876: =(AE2876)*AA2876/Y2876 -> 1733.2907 | AL2876: =AK2876*(1-L2876-M2876) -> 1273.9687 | AM2876: =AE2876-AI2876-AL2876-AJ2876 -> 1295.0842 | AN2876: =Z2876-366 -> 45715 | AO2876: =IF(AND(O2876>Z2876,N2876>AN2876),AE2876,0) -> 3495.31
A2877: Valid | B2877: 202509 | C2877: GMC023220100CALDERYS | D2877: CALDERYS INDIA REFRACTORIES LIMITED | E2877: 45901 | F2877: 46265 | G2877: Kiran Bai | H2877: 44921 | I2877: 27395 | J2877: ACK.4A9F3020250679.1 | K2877: =N2877 -> 45901 | L2877: =IF(K2877>=DATE(2022,4,1),4%,5%) -> 0.04 | M2877: 0.225 | N2877: 45901 | O2877: 46265 | R2877: 50 | S2877: =VLOOKUP(R2877,SA!$B$3:$C$11,2,1) -> 46-55 | T2877: Female | U2877: Mother | V2877: 300000 | W2877: =IF(U2877="self",V2877,0) -> 0 | X2877: =IF(U2877="self",1,0) -> 0 | Y2877: =O2877-N2877+1 -> 365 | Z2877: =$Z$1 -> 46081 | AA2877: =IF(MIN((Z2877-N2877)+1,Y2877)<0,0,MIN((Z2877-N2877)+1,Y2877)) -> 181 | AB2877: Maharashtra | AC2877: =AE2877+AF2877+AG2877+AH2877 -> 7373.466 | AD2877: 1 | AE2877: =INDEX(SA!$C$2:$G$11,MATCH(Details!S2877,SA!$C$2:$C$11,0),MATCH(Details!V2877,SA!$C$2:$G$2,0))*Y2877/(F2877-E2877+1) -> 6248.7 | AF2877: =IF(AB2877="Karnataka",AE2877*9%,0) -> 0 | AG2877: =IF(AB2877="Karnataka",AE2877*9%,0) -> 0 | AH2877: =IF(AF2877+AG2877>0,0,AE2877*18%) -> 1124.766 | AI2877: =AE2877*L2877 -> 249.948 | AJ2877: =$AE2877*M2877 -> 1405.9575 | AK2877: =(AE2877)*AA2877/Y2877 -> 3098.6704 | AL2877: =AK2877*(1-L2877-M2877) -> 2277.5228 | AM2877: =AE2877-AI2877-AL2877-AJ2877 -> 2315.2717 | AN2877: =Z2877-366 -> 45715 | AO2877: =IF(AND(O2877>Z2877,N2877>AN2877),AE2877,0) -> 6248.7
A2878: Valid | B2878: 202509 | C2878: GMC023220100CALDERYS | D2878: CALDERYS INDIA REFRACTORIES LIMITED | E2878: 45901 | F2878: 46265 | G2878: Ritu Dubey | H2878: 44921 | I2878: 34905 | J2878: ACK.4A9F3020250679.2 | K2878: =N2878 -> 45901 | L2878: =IF(K2878>=DATE(2022,4,1),4%,5%) -> 0.04 | M2878: 0.225 | N2878: 45901 | O2878: 46265 | R2878: 30 | S2878: =VLOOKUP(R2878,SA!$B$3:$C$11,2,1) -> 26-35 | T2878: Female | U2878: Spouse | V2878: 300000 | W2878: =IF(U2878="self",V2878,0) -> 0 | X2878: =IF(U2878="self",1,0) -> 0 | Y2878: =O2878-N2878+1 -> 365 | Z2878: =$Z$1 -> 46081 | AA2878: =IF(MIN((Z2878-N2878)+1,Y2878)<0,0,MIN((Z2878-N2878)+1,Y2878)) -> 181 | AB2878: Maharashtra | AC2878: =AE2878+AF2878+AG2878+AH2878 -> 4124.4658 | AD2878: 1 | AE2878: =INDEX(SA!$C$2:$G$11,MATCH(Details!S2878,SA!$C$2:$C$11,0),MATCH(Details!V2878,SA!$C$2:$G$2,0))*Y2878/(F2878-E2878+1) -> 3495.31 | AF2878: =IF(AB2878="Karnataka",AE2878*9%,0) -> 0 | AG2878: =IF(AB2878="Karnataka",AE2878*9%,0) -> 0 | AH2878: =IF(AF2878+AG2878>0,0,AE2878*18%) -> 629.1558 | AI2878: =AE2878*L2878 -> 139.8124 | AJ2878: =$AE2878*M2878 -> 786.44475 | AK2878: =(AE2878)*AA2878/Y2878 -> 1733.2907 | AL2878: =AK2878*(1-L2878-M2878) -> 1273.9687 | AM2878: =AE2878-AI2878-AL2878-AJ2878 -> 1295.0842 | AN2878: =Z2878-366 -> 45715 | AO2878: =IF(AND(O2878>Z2878,N2878>AN2878),AE2878,0) -> 3495.31
A2879: Valid | B2879: 202509 | C2879: GMC023220100CALDERYS | D2879: CALDERYS INDIA REFRACTORIES LIMITED | E2879: 45901 | F2879: 46265 | G2879: Raksha Dubey | H2879: 44921 | I2879: 45523 | J2879: ACK.4A9F3020250679.3 | K2879: =N2879 -> 45901 | L2879: =IF(K2879>=DATE(2022,4,1),4%,5%) -> 0.04 | M2879: 0.225 | N2879: 45901 | O2879: 46265 | R2879: 1 | S2879: =VLOOKUP(R2879,SA!$B$3:$C$11,2,1) -> 0-25 | T2879: Female | U2879: Daughter | V2879: 300000 | W2879: =IF(U2879="self",V2879,0) -> 0 | X2879: =IF(U2879="self",1,0) -> 0 | Y2879: =O2879-N2879+1 -> 365 | Z2879: =$Z$1 -> 46081 | AA2879: =IF(MIN((Z2879-N2879)+1,Y2879)<0,0,MIN((Z2879-N2879)+1,Y2879)) -> 181 | AB2879: Maharashtra | AC2879: =AE2879+AF2879+AG2879+AH2879 -> 3690.3792 | AD2879: 1 | AE2879: =INDEX(SA!$C$2:$G$11,MATCH(Details!S2879,SA!$C$2:$C$11,0),MATCH(Details!V2879,SA!$C$2:$G$2,0))*Y2879/(F2879-E2879+1) -> 3127.44 | AF2879: =IF(AB2879="Karnataka",AE2879*9%,0) -> 0 | AG2879: =IF(AB2879="Karnataka",AE2879*9%,0) -> 0 | AH2879: =IF(AF2879+AG2879>0,0,AE2879*18%) -> 562.9392 | AI2879: =AE2879*L2879 -> 125.0976 | AJ2879: =$AE2879*M2879 -> 703.674 | AK2879: =(AE2879)*AA2879/Y2879 -> 1550.8675 | AL2879: =AK2879*(1-L2879-M2879) -> 1139.8876 | AM2879: =AE2879-AI2879-AL2879-AJ2879 -> 1158.7808 | AN2879: =Z2879-366 -> 45715 | AO2879: =IF(AND(O2879>Z2879,N2879>AN2879),AE2879,0) -> 3127.44
A2880: Valid | B2880: 202509 | C2880: GMC023220100CALDERYS | D2880: CALDERYS INDIA REFRACTORIES LIMITED | E2880: 45901 | F2880: 46265 | G2880: Rajendra Prasad | H2880: 44921 | I2880: 22384 | J2880: ACK.4A9F3020250679.4 | K2880: =N2880 -> 45901 | L2880: =IF(K2880>=DATE(2022,4,1),4%,5%) -> 0.04 | M2880: 0.225 | N2880: 45901 | O2880: 46265 | R2880: 64 | S2880: =VLOOKUP(R2880,SA!$B$3:$C$11,2,1) -> 56-65 | T2880: Male | U2880: Father | V2880: 300000 | W2880: =IF(U2880="self",V2880,0) -> 0 | X2880: =IF(U2880="self",1,0) -> 0 | Y2880: =O2880-N2880+1 -> 365 | Z2880: =$Z$1 -> 46081 | AA2880: =IF(MIN((Z2880-N2880)+1,Y2880)<0,0,MIN((Z2880-N2880)+1,Y2880)) -> 181 | AB2880: Maharashtra | AC2880: =AE2880+AF2880+AG2880+AH2880 -> 10831.751 | AD2880: 1 | AE2880: =INDEX(SA!$C$2:$G$11,MATCH(Details!S2880,SA!$C$2:$C$11,0),MATCH(Details!V2880,SA!$C$2:$G$2,0))*Y2880/(F2880-E2880+1) -> 9179.45 | AF2880: =IF(AB2880="Karnataka",AE2880*9%,0) -> 0 | AG2880: =IF(AB2880="Karnataka",AE2880*9%,0) -> 0 | AH2880: =IF(AF2880+AG2880>0,0,AE2880*18%) -> 1652.301 | AI2880: =AE2880*L2880 -> 367.178 | AJ2880: =$AE2880*M2880 -> 2065.3763 | AK2880: =(AE2880)*AA2880/Y2880 -> 4552.0012 | AL2880: =AK2880*(1-L2880-M2880) -> 3345.7209 | AM2880: =AE2880-AI2880-AL2880-AJ2880 -> 3401.1748 | AN2880: =Z2880-366 -> 45715 | AO2880: =IF(AND(O2880>Z2880,N2880>AN2880),AE2880,0) -> 9179.45
A2881: Valid | B2881: 202509 | C2881: GMC023220100CALDERYS | D2881: CALDERYS INDIA REFRACTORIES LIMITED | E2881: 45901 | F2881: 46265 | G2881: Sateesh Kumar | H2881: 44921 | I2881: 32838 | J2881: ACK.4A9F3020250679.5 | K2881: =N2881 -> 45901 | L2881: =IF(K2881>=DATE(2022,4,1),4%,5%) -> 0.04 | M2881: 0.225 | N2881: 45901 | O2881: 46265 | R2881: 35 | S2881: =VLOOKUP(R2881,SA!$B$3:$C$11,2,1) -> 26-35 | T2881: Male | U2881: Self | V2881: 300000 | W2881: =IF(U2881="self",V2881,0) -> 300000 | X2881: =IF(U2881="self",1,0) -> 1 | Y2881: =O2881-N2881+1 -> 365 | Z2881: =$Z$1 -> 46081 | AA2881: =IF(MIN((Z2881-N2881)+1,Y2881)<0,0,MIN((Z2881-N2881)+1,Y2881)) -> 181 | AB2881: Maharashtra | AC2881: =AE2881+AF2881+AG2881+AH2881 -> 4124.4658 | AD2881: 1 | AE2881: =INDEX(SA!$C$2:$G$11,MATCH(Details!S2881,SA!$C$2:$C$11,0),MATCH(Details!V2881,SA!$C$2:$G$2,0))*Y2881/(F2881-E2881+1) -> 3495.31 | AF2881: =IF(AB2881="Karnataka",AE2881*9%,0) -> 0 | AG2881: =IF(AB2881="Karnataka",AE2881*9%,0) -> 0 | AH2881: =IF(AF2881+AG2881>0,0,AE2881*18%) -> 629.1558 | AI2881: =AE2881*L2881 -> 139.8124 | AJ2881: =$AE2881*M2881 -> 786.44475 | AK2881: =(AE2881)*AA2881/Y2881 -> 1733.2907 | AL2881: =AK2881*(1-L2881-M2881) -> 1273.9687 | AM2881: =AE2881-AI2881-AL2881-AJ2881 -> 1295.0842 | AN2881: =Z2881-366 -> 45715 | AO2881: =IF(AND(O2881>Z2881,N2881>AN2881),AE2881,0) -> 3495.31
A2882: Valid | B2882: 202509 | C2882: GMC023220100CALDERYS | D2882: CALDERYS INDIA REFRACTORIES LIMITED | E2882: 45901 | F2882: 46265 | G2882: Kundan Devi | H2882: 45011 | I2882: 31778 | J2882: ACK.4A9F3020250695.1 | K2882: =N2882 -> 45901 | L2882: =IF(K2882>=DATE(2022,4,1),4%,5%) -> 0.04 | M2882: 0.225 | N2882: 45901 | O2882: 46265 | R2882: 38 | S2882: =VLOOKUP(R2882,SA!$B$3:$C$11,2,1) -> 36-45 | T2882: Female | U2882: Mother | V2882: 400000 | W2882: =IF(U2882="self",V2882,0) -> 0 | X2882: =IF(U2882="self",1,0) -> 0 | Y2882: =O2882-N2882+1 -> 365 | Z2882: =$Z$1 -> 46081 | AA2882: =IF(MIN((Z2882-N2882)+1,Y2882)<0,0,MIN((Z2882-N2882)+1,Y2882)) -> 181 | AB2882: Maharashtra | AC2882: =AE2882+AF2882+AG2882+AH2882 -> 5496.5226 | AD2882: 1 | AE2882: =INDEX(SA!$C$2:$G$11,MATCH(Details!S2882,SA!$C$2:$C$11,0),MATCH(Details!V2882,SA!$C$2:$G$2,0))*Y2882/(F2882-E2882+1) -> 4658.07 | AF2882: =IF(AB2882="Karnataka",AE2882*9%,0) -> 0 | AG2882: =IF(AB2882="Karnataka",AE2882*9%,0) -> 0 | AH2882: =IF(AF2882+AG2882>0,0,AE2882*18%) -> 838.4526 | AI2882: =AE2882*L2882 -> 186.3228 | AJ2882: =$AE2882*M2882 -> 1048.0657 | AK2882: =(AE2882)*AA2882/Y2882 -> 2309.8922 | AL2882: =AK2882*(1-L2882-M2882) -> 1697.7708 | AM2882: =AE2882-AI2882-AL2882-AJ2882 -> 1725.9106 | AN2882: =Z2882-366 -> 45715 | AO2882: =IF(AND(O2882>Z2882,N2882>AN2882),AE2882,0) -> 4658.07
A2883: Valid | B2883: 202509 | C2883: GMC023220100CALDERYS | D2883: CALDERYS INDIA REFRACTORIES LIMITED | E2883: 45901 | F2883: 46265 | G2883: Priti Priya | H2883: 45011 | I2883: 37363 | J2883: ACK.4A9F3020250695.2 | K2883: =N2883 -> 45901 | L2883: =IF(K2883>=DATE(2022,4,1),4%,5%) -> 0.04 | M2883: 0.225 | N2883: 45901 | O2883: 46265 | R2883: 23 | S2883: =VLOOKUP(R2883,SA!$B$3:$C$11,2,1) -> 0-25 | T2883: Female | U2883: Self | V2883: 400000 | W2883: =IF(U2883="self",V2883,0) -> 400000 | X2883: =IF(U2883="self",1,0) -> 1 | Y2883: =O2883-N2883+1 -> 365 | Z2883: =$Z$1 -> 46081 | AA2883: =IF(MIN((Z2883-N2883)+1,Y2883)<0,0,MIN((Z2883-N2883)+1,Y2883)) -> 181 | AB2883: Maharashtra | AC2883: =AE2883+AF2883+AG2883+AH2883 -> 4043.8364 | AD2883: 1 | AE2883: =INDEX(SA!$C$2:$G$11,MATCH(Details!S2883,SA!$C$2:$C$11,0),MATCH(Details!V2883,SA!$C$2:$G$2,0))*Y2883/(F2883-E2883+1) -> 3426.98 | AF2883: =IF(AB2883="Karnataka",AE2883*9%,0) -> 0 | AG2883: =IF(AB2883="Karnataka",AE2883*9%,0) -> 0 | AH2883: =IF(AF2883+AG2883>0,0,AE2883*18%) -> 616.8564 | AI2883: =AE2883*L2883 -> 137.0792 | AJ2883: =$AE2883*M2883 -> 771.0705 | AK2883: =(AE2883)*AA2883/Y2883 -> 1699.4065 | AL2883: =AK2883*(1-L2883-M2883) -> 1249.0638 | AM2883: =AE2883-AI2883-AL2883-AJ2883 -> 1269.7665 | AN2883: =Z2883-366 -> 45715 | AO2883: =IF(AND(O2883>Z2883,N2883>AN2883),AE2883,0) -> 3426.98
A2884: Valid | B2884: 202509 | C2884: GMC023220100CALDERYS | D2884: CALDERYS INDIA REFRACTORIES LIMITED | E2884: 45901 | F2884: 46265 | G2884: Arun Ray | H2884: 45011 | I2884: 31079 | J2884: ACK.4A9F3020250695.3 | K2884: =N2884 -> 45901 | L2884: =IF(K2884>=DATE(2022,4,1),4%,5%) -> 0.04 | M2884: 0.225 | N2884: 45901 | O2884: 46265 | R2884: 40 | S2884: =VLOOKUP(R2884,SA!$B$3:$C$11,2,1) -> 36-45 | T2884: Male | U2884: Father | V2884: 400000 | W2884: =IF(U2884="self",V2884,0) -> 0 | X2884: =IF(U2884="self",1,0) -> 0 | Y2884: =O2884-N2884+1 -> 365 | Z2884: =$Z$1 -> 46081 | AA2884: =IF(MIN((Z2884-N2884)+1,Y2884)<0,0,MIN((Z2884-N2884)+1,Y2884)) -> 181 | AB2884: Maharashtra | AC2884: =AE2884+AF2884+AG2884+AH2884 -> 5496.5226 | AD2884: 1 | AE2884: =INDEX(SA!$C$2:$G$11,MATCH(Details!S2884,SA!$C$2:$C$11,0),MATCH(Details!V2884,SA!$C$2:$G$2,0))*Y2884/(F2884-E2884+1) -> 4658.07 | AF2884: =IF(AB2884="Karnataka",AE2884*9%,0) -> 0 | AG2884: =IF(AB2884="Karnataka",AE2884*9%,0) -> 0 | AH2884: =IF(AF2884+AG2884>0,0,AE2884*18%) -> 838.4526 | AI2884: =AE2884*L2884 -> 186.3228 | AJ2884: =$AE2884*M2884 -> 1048.0657 | AK2884: =(AE2884)*AA2884/Y2884 -> 2309.8922 | AL2884: =AK2884*(1-L2884-M2884) -> 1697.7708 | AM2884: =AE2884-AI2884-AL2884-AJ2884 -> 1725.9106 | AN2884: =Z2884-366 -> 45715 | AO2884: =IF(AND(O2884>Z2884,N2884>AN2884),AE2884,0) -> 4658.07
A2885: Valid | B2885: 202509 | C2885: GMC023220100CALDERYS | D2885: CALDERYS INDIA REFRACTORIES LIMITED | E2885: 45901 | F2885: 46265 | G2885: Ranjan Niranjan Amte | H2885: 45020 | I2885: 18785 | J2885: ACK.4A9F3020250703.1 | K2885: =N2885 -> 45901 | L2885: =IF(K2885>=DATE(2022,4,1),4%,5%) -> 0.04 | M2885: 0.225 | N2885: 45901 | O2885: 46265 | R2885: 74 | S2885: =VLOOKUP(R2885,SA!$B$3:$C$11,2,1) -> 71-75 | T2885: Female | U2885: Mother | V2885: 500000 | W2885: =IF(U2885="self",V2885,0) -> 0 | X2885: =IF(U2885="self",1,0) -> 0 | Y2885: =O2885-N2885+1 -> 365 | Z2885: =$Z$1 -> 46081 | AA2885: =IF(MIN((Z2885-N2885)+1,Y2885)<0,0,MIN((Z2885-N2885)+1,Y2885)) -> 181 | AB2885: Maharashtra | AC2885: =AE2885+AF2885+AG2885+AH2885 -> 23735.924 | AD2885: 1 | AE2885: =INDEX(SA!$C$2:$G$11,MATCH(Details!S2885,SA!$C$2:$C$11,0),MATCH(Details!V2885,SA!$C$2:$G$2,0))*Y2885/(F2885-E2885+1) -> 20115.19 | AF2885: =IF(AB2885="Karnataka",AE2885*9%,0) -> 0 | AG2885: =IF(AB2885="Karnataka",AE2885*9%,0) -> 0 | AH2885: =IF(AF2885+AG2885>0,0,AE2885*18%) -> 3620.7342 | AI2885: =AE2885*L2885 -> 804.6076 | AJ2885: =$AE2885*M2885 -> 4525.9177 | AK2885: =(AE2885)*AA2885/Y2885 -> 9974.9298 | AL2885: =AK2885*(1-L2885-M2885) -> 7331.5734 | AM2885: =AE2885-AI2885-AL2885-AJ2885 -> 7453.0912 | AN2885: =Z2885-366 -> 45715 | AO2885: =IF(AND(O2885>Z2885,N2885>AN2885),AE2885,0) -> 20115.19
A2886: Valid | B2886: 202509 | C2886: GMC023220100CALDERYS | D2886: CALDERYS INDIA REFRACTORIES LIMITED | E2886: 45901 | F2886: 46265 | G2886: Aparna Amte | H2886: 45020 | I2886: 30936 | J2886: ACK.4A9F3020250703.2 | K2886: =N2886 -> 45901 | L2886: =IF(K2886>=DATE(2022,4,1),4%,5%) -> 0.04 | M2886: 0.225 | N2886: 45901 | O2886: 46265 | R2886: 40 | S2886: =VLOOKUP(R2886,SA!$B$3:$C$11,2,1) -> 36-45 | T2886: Female | U2886: Self | V2886: 500000 | W2886: =IF(U2886="self",V2886,0) -> 500000 | X2886: =IF(U2886="self",1,0) -> 1 | Y2886: =O2886-N2886+1 -> 365 | Z2886: =$Z$1 -> 46081 | AA2886: =IF(MIN((Z2886-N2886)+1,Y2886)<0,0,MIN((Z2886-N2886)+1,Y2886)) -> 181 | AB2886: Maharashtra | AC2886: =AE2886+AF2886+AG2886+AH2886 -> 6046.1902 | AD2886: 1 | AE2886: =INDEX(SA!$C$2:$G$11,MATCH(Details!S2886,SA!$C$2:$C$11,0),MATCH(Details!V2886,SA!$C$2:$G$2,0))*Y2886/(F2886-E2886+1) -> 5123.89 | AF2886: =IF(AB2886="Karnataka",AE2886*9%,0) -> 0 | AG2886: =IF(AB2886="Karnataka",AE2886*9%,0) -> 0 | AH2886: =IF(AF2886+AG2886>0,0,AE2886*18%) -> 922.3002 | AI2886: =AE2886*L2886 -> 204.9556 | AJ2886: =$AE2886*M2886 -> 1152.8753 | AK2886: =(AE2886)*AA2886/Y2886 -> 2540.8879 | AL2886: =AK2886*(1-L2886-M2886) -> 1867.5526 | AM2886: =AE2886-AI2886-AL2886-AJ2886 -> 1898.5065 | AN2886: =Z2886-366 -> 45715 | AO2886: =IF(AND(O2886>Z2886,N2886>AN2886),AE2886,0) -> 5123.89
A2887: Valid | B2887: 202509 | C2887: GMC023220100CALDERYS | D2887: CALDERYS INDIA REFRACTORIES LIMITED | E2887: 45901 | F2887: 46265 | G2887: Niranjan Narayan Amte | H2887: 45020 | I2887: 18471 | J2887: ACK.4A9F3020250703.3 | K2887: =N2887 -> 45901 | L2887: =IF(K2887>=DATE(2022,4,1),4%,5%) -> 0.04 | M2887: 0.225 | N2887: 45901 | O2887: 46265 | R2887: 75 | S2887: =VLOOKUP(R2887,SA!$B$3:$C$11,2,1) -> 71-75 | T2887: Male | U2887: Father | V2887: 500000 | W2887: =IF(U2887="self",V2887,0) -> 0 | X2887: =IF(U2887="self",1,0) -> 0 | Y2887: =O2887-N2887+1 -> 365 | Z2887: =$Z$1 -> 46081 | AA2887: =IF(MIN((Z2887-N2887)+1,Y2887)<0,0,MIN((Z2887-N2887)+1,Y2887)) -> 181 | AB2887: Maharashtra | AC2887: =AE2887+AF2887+AG2887+AH2887 -> 23735.924 | AD2887: 1 | AE2887: =INDEX(SA!$C$2:$G$11,MATCH(Details!S2887,SA!$C$2:$C$11,0),MATCH(Details!V2887,SA!$C$2:$G$2,0))*Y2887/(F2887-E2887+1) -> 20115.19 | AF2887: =IF(AB2887="Karnataka",AE2887*9%,0) -> 0 | AG2887: =IF(AB2887="Karnataka",AE2887*9%,0) -> 0 | AH2887: =IF(AF2887+AG2887>0,0,AE2887*18%) -> 3620.7342 | AI2887: =AE2887*L2887 -> 804.6076 | AJ2887: =$AE2887*M2887 -> 4525.9177 | AK2887: =(AE2887)*AA2887/Y2887 -> 9974.9298 | AL2887: =AK2887*(1-L2887-M2887) -> 7331.5734 | AM2887: =AE2887-AI2887-AL2887-AJ2887 -> 7453.0912 | AN2887: =Z2887-366 -> 45715 | AO2887: =IF(AND(O2887>Z2887,N2887>AN2887),AE2887,0) -> 20115.19
A2888: Valid | B2888: 202509 | C2888: GMC023220100CALDERYS | D2888: CALDERYS INDIA REFRACTORIES LIMITED | E2888: 45901 | F2888: 46265 | G2888: Gaurav Bhatnagar | H2888: 45020 | I2888: 29321 | J2888: ACK.4A9F3020250703.4 | K2888: =N2888 -> 45901 | L2888: =IF(K2888>=DATE(2022,4,1),4%,5%) -> 0.04 | M2888: 0.225 | N2888: 45901 | O2888: 46265 | R2888: 45 | S2888: =VLOOKUP(R2888,SA!$B$3:$C$11,2,1) -> 36-45 | T2888: Male | U2888: Spouse | V2888: 500000 | W2888: =IF(U2888="self",V2888,0) -> 0 | X2888: =IF(U2888="self",1,0) -> 0 | Y2888: =O2888-N2888+1 -> 365 | Z2888: =$Z$1 -> 46081 | AA2888: =IF(MIN((Z2888-N2888)+1,Y2888)<0,0,MIN((Z2888-N2888)+1,Y2888)) -> 181 | AB2888: Maharashtra | AC2888: =AE2888+AF2888+AG2888+AH2888 -> 6046.1902 | AD2888: 1 | AE2888: =INDEX(SA!$C$2:$G$11,MATCH(Details!S2888,SA!$C$2:$C$11,0),MATCH(Details!V2888,SA!$C$2:$G$2,0))*Y2888/(F2888-E2888+1) -> 5123.89 | AF2888: =IF(AB2888="Karnataka",AE2888*9%,0) -> 0 | AG2888: =IF(AB2888="Karnataka",AE2888*9%,0) -> 0 | AH2888: =IF(AF2888+AG2888>0,0,AE2888*18%) -> 922.3002 | AI2888: =AE2888*L2888 -> 204.9556 | AJ2888: =$AE2888*M2888 -> 1152.8753 | AK2888: =(AE2888)*AA2888/Y2888 -> 2540.8879 | AL2888: =AK2888*(1-L2888-M2888) -> 1867.5526 | AM2888: =AE2888-AI2888-AL2888-AJ2888 -> 1898.5065 | AN2888: =Z2888-366 -> 45715 | AO2888: =IF(AND(O2888>Z2888,N2888>AN2888),AE2888,0) -> 5123.89
A2889: Valid | B2889: 202509 | C2889: GMC023220100CALDERYS | D2889: CALDERYS INDIA REFRACTORIES LIMITED | E2889: 45901 | F2889: 46265 | G2889: Gandhari Mahato | H2889: 45012 | I2889: 32136 | J2889: ACK.4A9F3020250697.1 | K2889: =N2889 -> 45901 | L2889: =IF(K2889>=DATE(2022,4,1),4%,5%) -> 0.04 | M2889: 0.225 | N2889: 45901 | O2889: 46265 | R2889: 37 | S2889: =VLOOKUP(R2889,SA!$B$3:$C$11,2,1) -> 36-45 | T2889: Female | U2889: Mother | V2889: 400000 | W2889: =IF(U2889="self",V2889,0) -> 0 | X2889: =IF(U2889="self",1,0) -> 0 | Y2889: =O2889-N2889+1 -> 365 | Z2889: =$Z$1 -> 46081 | AA2889: =IF(MIN((Z2889-N2889)+1,Y2889)<0,0,MIN((Z2889-N2889)+1,Y2889)) -> 181 | AB2889: Maharashtra | AC2889: =AE2889+AF2889+AG2889+AH2889 -> 5496.5226 | AD2889: 1 | AE2889: =INDEX(SA!$C$2:$G$11,MATCH(Details!S2889,SA!$C$2:$C$11,0),MATCH(Details!V2889,SA!$C$2:$G$2,0))*Y2889/(F2889-E2889+1) -> 4658.07 | AF2889: =IF(AB2889="Karnataka",AE2889*9%,0) -> 0 | AG2889: =IF(AB2889="Karnataka",AE2889*9%,0) -> 0 | AH2889: =IF(AF2889+AG2889>0,0,AE2889*18%) -> 838.4526 | AI2889: =AE2889*L2889 -> 186.3228 | AJ2889: =$AE2889*M2889 -> 1048.0657 | AK2889: =(AE2889)*AA2889/Y2889 -> 2309.8922 | AL2889: =AK2889*(1-L2889-M2889) -> 1697.7708 | AM2889: =AE2889-AI2889-AL2889-AJ2889 -> 1725.9106 | AN2889: =Z2889-366 -> 45715 | AO2889: =IF(AND(O2889>Z2889,N2889>AN2889),AE2889,0) -> 4658.07
A2890: Valid | B2890: 202509 | C2890: GMC023220100CALDERYS | D2890: CALDERYS INDIA REFRACTORIES LIMITED | E2890: 45901 | F2890: 46265 | G2890: Roshni Mahato | H2890: 45012 | I2890: 38576 | J2890: ACK.4A9F3020250697.2 | K2890: =N2890 -> 45901 | L2890: =IF(K2890>=DATE(2022,4,1),4%,5%) -> 0.04 | M2890: 0.225 | N2890: 45901 | O2890: 46265 | R2890: 20 | S2890: =VLOOKUP(R2890,SA!$B$3:$C$11,2,1) -> 0-25 | T2890: Female | U2890: Self | V2890: 400000 | W2890: =IF(U2890="self",V2890,0) -> 400000 | X2890: =IF(U2890="self",1,0) -> 1 | Y2890: =O2890-N2890+1 -> 365 | Z2890: =$Z$1 -> 46081 | AA2890: =IF(MIN((Z2890-N2890)+1,Y2890)<0,0,MIN((Z2890-N2890)+1,Y2890)) -> 181 | AB2890: Maharashtra | AC2890: =AE2890+AF2890+AG2890+AH2890 -> 4043.8364 | AD2890: 1 | AE2890: =INDEX(SA!$C$2:$G$11,MATCH(Details!S2890,SA!$C$2:$C$11,0),MATCH(Details!V2890,SA!$C$2:$G$2,0))*Y2890/(F2890-E2890+1) -> 3426.98 | AF2890: =IF(AB2890="Karnataka",AE2890*9%,0) -> 0 | AG2890: =IF(AB2890="Karnataka",AE2890*9%,0) -> 0 | AH2890: =IF(AF2890+AG2890>0,0,AE2890*18%) -> 616.8564 | AI2890: =AE2890*L2890 -> 137.0792 | AJ2890: =$AE2890*M2890 -> 771.0705 | AK2890: =(AE2890)*AA2890/Y2890 -> 1699.4065 | AL2890: =AK2890*(1-L2890-M2890) -> 1249.0638 | AM2890: =AE2890-AI2890-AL2890-AJ2890 -> 1269.7665 | AN2890: =Z2890-366 -> 45715 | AO2890: =IF(AND(O2890>Z2890,N2890>AN2890),AE2890,0) -> 3426.98
A2891: Valid | B2891: 202509 | C2891: GMC023220100CALDERYS | D2891: CALDERYS INDIA REFRACTORIES LIMITED | E2891: 45901 | F2891: 46265 | G2891: Subhas Mahato | H2891: 45012 | I2891: 30127 | J2891: ACK.4A9F3020250697.3 | K2891: =N2891 -> 45901 | L2891: =IF(K2891>=DATE(2022,4,1),4%,5%) -> 0.04 | M2891: 0.225 | N2891: 45901 | O2891: 46265 | R2891: 43 | S2891: =VLOOKUP(R2891,SA!$B$3:$C$11,2,1) -> 36-45 | T2891: Male | U2891: Father | V2891: 400000 | W2891: =IF(U2891="self",V2891,0) -> 0 | X2891: =IF(U2891="self",1,0) -> 0 | Y2891: =O2891-N2891+1 -> 365 | Z2891: =$Z$1 -> 46081 | AA2891: =IF(MIN((Z2891-N2891)+1,Y2891)<0,0,MIN((Z2891-N2891)+1,Y2891)) -> 181 | AB2891: Maharashtra | AC2891: =AE2891+AF2891+AG2891+AH2891 -> 5496.5226 | AD2891: 1 | AE2891: =INDEX(SA!$C$2:$G$11,MATCH(Details!S2891,SA!$C$2:$C$11,0),MATCH(Details!V2891,SA!$C$2:$G$2,0))*Y2891/(F2891-E2891+1) -> 4658.07 | AF2891: =IF(AB2891="Karnataka",AE2891*9%,0) -> 0 | AG2891: =IF(AB2891="Karnataka",AE2891*9%,0) -> 0 | AH2891: =IF(AF2891+AG2891>0,0,AE2891*18%) -> 838.4526 | AI2891: =AE2891*L2891 -> 186.3228 | AJ2891: =$AE2891*M2891 -> 1048.0657 | AK2891: =(AE2891)*AA2891/Y2891 -> 2309.8922 | AL2891: =AK2891*(1-L2891-M2891) -> 1697.7708 | AM2891: =AE2891-AI2891-AL2891-AJ2891 -> 1725.9106 | AN2891: =Z2891-366 -> 45715 | AO2891: =IF(AND(O2891>Z2891,N2891>AN2891),AE2891,0) -> 4658.07
A2892: Valid | B2892: 202509 | C2892: GMC023220100CALDERYS | D2892: CALDERYS INDIA REFRACTORIES LIMITED | E2892: 45901 | F2892: 46265 | G2892: Prabha Deshmukh | H2892: 45056 | I2892: 20580 | J2892: ACK.4A9F3020250708.1 | K2892: =N2892 -> 45901 | L2892: =IF(K2892>=DATE(2022,4,1),4%,5%) -> 0.04 | M2892: 0.225 | N2892: 45901 | O2892: 46265 | R2892: 69 | S2892: =VLOOKUP(R2892,SA!$B$3:$C$11,2,1) -> 66-70 | T2892: Female | U2892: Mother | V2892: 500000 | W2892: =IF(U2892="self",V2892,0) -> 0 | X2892: =IF(U2892="self",1,0) -> 0 | Y2892: =O2892-N2892+1 -> 365 | Z2892: =$Z$1 -> 46081 | AA2892: =IF(MIN((Z2892-N2892)+1,Y2892)<0,0,MIN((Z2892-N2892)+1,Y2892)) -> 181 | AB2892: Maharashtra | AC2892: =AE2892+AF2892+AG2892+AH2892 -> 18713.136 | AD2892: 1 | AE2892: =INDEX(SA!$C$2:$G$11,MATCH(Details!S2892,SA!$C$2:$C$11,0),MATCH(Details!V2892,SA!$C$2:$G$2,0))*Y2892/(F2892-E2892+1) -> 15858.59 | AF2892: =IF(AB2892="Karnataka",AE2892*9%,0) -> 0 | AG2892: =IF(AB2892="Karnataka",AE2892*9%,0) -> 0 | AH2892: =IF(AF2892+AG2892>0,0,AE2892*18%) -> 2854.5462 | AI2892: =AE2892*L2892 -> 634.3436 | AJ2892: =$AE2892*M2892 -> 3568.1827 | AK2892: =(AE2892)*AA2892/Y2892 -> 7864.1227 | AL2892: =AK2892*(1-L2892-M2892) -> 5780.1302 | AM2892: =AE2892-AI2892-AL2892-AJ2892 -> 5875.9335 | AN2892: =Z2892-366 -> 45715 | AO2892: =IF(AND(O2892>Z2892,N2892>AN2892),AE2892,0) -> 15858.59
A2893: Valid | B2893: 202509 | C2893: GMC023220100CALDERYS | D2893: CALDERYS INDIA REFRACTORIES LIMITED | E2893: 45901 | F2893: 46265 | G2893: Ashwini Deshmukh | H2893: 45056 | I2893: 32278 | J2893: ACK.4A9F3020250708.2 | K2893: =N2893 -> 45901 | L2893: =IF(K2893>=DATE(2022,4,1),4%,5%) -> 0.04 | M2893: 0.225 | N2893: 45901 | O2893: 46265 | R2893: 37 | S2893: =VLOOKUP(R2893,SA!$B$3:$C$11,2,1) -> 36-45 | T2893: Female | U2893: Spouse | V2893: 500000 | W2893: =IF(U2893="self",V2893,0) -> 0 | X2893: =IF(U2893="self",1,0) -> 0 | Y2893: =O2893-N2893+1 -> 365 | Z2893: =$Z$1 -> 46081 | AA2893: =IF(MIN((Z2893-N2893)+1,Y2893)<0,0,MIN((Z2893-N2893)+1,Y2893)) -> 181 | AB2893: Maharashtra | AC2893: =AE2893+AF2893+AG2893+AH2893 -> 6046.1902 | AD2893: 1 | AE2893: =INDEX(SA!$C$2:$G$11,MATCH(Details!S2893,SA!$C$2:$C$11,0),MATCH(Details!V2893,SA!$C$2:$G$2,0))*Y2893/(F2893-E2893+1) -> 5123.89 | AF2893: =IF(AB2893="Karnataka",AE2893*9%,0) -> 0 | AG2893: =IF(AB2893="Karnataka",AE2893*9%,0) -> 0 | AH2893: =IF(AF2893+AG2893>0,0,AE2893*18%) -> 922.3002 | AI2893: =AE2893*L2893 -> 204.9556 | AJ2893: =$AE2893*M2893 -> 1152.8753 | AK2893: =(AE2893)*AA2893/Y2893 -> 2540.8879 | AL2893: =AK2893*(1-L2893-M2893) -> 1867.5526 | AM2893: =AE2893-AI2893-AL2893-AJ2893 -> 1898.5065 | AN2893: =Z2893-366 -> 45715 | AO2893: =IF(AND(O2893>Z2893,N2893>AN2893),AE2893,0) -> 5123.89
... A2897: Valid | B2897: 202509 | C2897: GMC023220100CALDERYS | D2897: CALDERYS INDIA REFRACTORIES LIMITED | E2897: 45901 | F2897: 46265 | G2897: Rahul Deshmukh | H2897: 45056 | I2897: 30980 | J2897: ACK.4A9F3020250708.6 | K2897: =N2897 -> 45901 | L2897: =IF(K2897>=DATE(2022,4,1),4%,5%) -> 0.04 | M2897: 0.225 | N2897: 45901 | O2897: 46265 | R2897: 40 | S2897: =VLOOKUP(R2897,SA!$B$3:$C$11,2,1) -> 36-45 | T2897: Male | U2897: Self | V2897: 500000 | W2897: =IF(U2897="self",V2897,0) -> 500000 | X2897: =IF(U2897="self",1,0) -> 1 | Y2897: =O2897-N2897+1 -> 365 | Z2897: =$Z$1 -> 46081 | AA2897: =IF(MIN((Z2897-N2897)+1,Y2897)<0,0,MIN((Z2897-N2897)+1,Y2897)) -> 181 | AB2897: Maharashtra | AC2897: =AE2897+AF2897+AG2897+AH2897 -> 6046.1902 | AD2897: 1 | AE2897: =INDEX(SA!$C$2:$G$11,MATCH(Details!S2897,SA!$C$2:$C$11,0),MATCH(Details!V2897,SA!$C$2:$G$2,0))*Y2897/(F2897-E2897+1) -> 5123.89 | AF2897: =IF(AB2897="Karnataka",AE2897*9%,0) -> 0 | AG2897: =IF(AB2897="Karnataka",AE2897*9%,0) -> 0 | AH2897: =IF(AF2897+AG2897>0,0,AE2897*18%) -> 922.3002 | AI2897: =AE2897*L2897 -> 204.9556 | AJ2897: =$AE2897*M2897 -> 1152.8753 | AK2897: =(AE2897)*AA2897/Y2897 -> 2540.8879 | AL2897: =AK2897*(1-L2897-M2897) -> 1867.5526 | AM2897: =AE2897-AI2897-AL2897-AJ2897 -> 1898.5065 | AN2897: =Z2897-366 -> 45715 | AO2897: =IF(AND(O2897>Z2897,N2897>AN2897),AE2897,0) -> 5123.89
A2898: Valid | B2898: 202509 | C2898: GMC023220100CALDERYS | D2898: CALDERYS INDIA REFRACTORIES LIMITED | E2898: 45901 | F2898: 46265 | G2898: Premlata singh | H2898: 45029 | I2898: 24842 | J2898: ACK.4A9F3020250709.1 | K2898: =N2898 -> 45901 | L2898: =IF(K2898>=DATE(2022,4,1),4%,5%) -> 0.04 | M2898: 0.225 | N2898: 45901 | O2898: 46265 | R2898: 57 | S2898: =VLOOKUP(R2898,SA!$B$3:$C$11,2,1) -> 56-65 | T2898: Female | U2898: Mother | V2898: 400000 | W2898: =IF(U2898="self",V2898,0) -> 0 | X2898: =IF(U2898="self",1,0) -> 0 | Y2898: =O2898-N2898+1 -> 365 | Z2898: =$Z$1 -> 46081 | AA2898: =IF(MIN((Z2898-N2898)+1,Y2898)<0,0,MIN((Z2898-N2898)+1,Y2898)) -> 181 | AB2898: Maharashtra | AC2898: =AE2898+AF2898+AG2898+AH2898 -> 11909.728 | AD2898: 1 | AE2898: =INDEX(SA!$C$2:$G$11,MATCH(Details!S2898,SA!$C$2:$C$11,0),MATCH(Details!V2898,SA!$C$2:$G$2,0))*Y2898/(F2898-E2898+1) -> 10092.99 | AF2898: =IF(AB2898="Karnataka",AE2898*9%,0) -> 0 | AG2898: =IF(AB2898="Karnataka",AE2898*9%,0) -> 0 | AH2898: =IF(AF2898+AG2898>0,0,AE2898*18%) -> 1816.7382 | AI2898: =AE2898*L2898 -> 403.7196 | AJ2898: =$AE2898*M2898 -> 2270.9228 | AK2898: =(AE2898)*AA2898/Y2898 -> 5005.017 | AL2898: =AK2898*(1-L2898-M2898) -> 3678.6875 | AM2898: =AE2898-AI2898-AL2898-AJ2898 -> 3739.6602 | AN2898: =Z2898-366 -> 45715 | AO2898: =IF(AND(O2898>Z2898,N2898>AN2898),AE2898,0) -> 10092.99
A2899: Valid | B2899: 202509 | C2899: GMC023220100CALDERYS | D2899: CALDERYS INDIA REFRACTORIES LIMITED | E2899: 45901 | F2899: 46265 | G2899: samar bahadur singh | H2899: 45029 | I2899: 25223 | J2899: ACK.4A9F3020250709.2 | K2899: =N2899 -> 45901 | L2899: =IF(K2899>=DATE(2022,4,1),4%,5%) -> 0.04 | M2899: 0.225 | N2899: 45901 | O2899: 46265 | R2899: 56 | S2899: =VLOOKUP(R2899,SA!$B$3:$C$11,2,1) -> 56-65 | T2899: Male | U2899: Father | V2899: 400000 | W2899: =IF(U2899="self",V2899,0) -> 0 | X2899: =IF(U2899="self",1,0) -> 0 | Y2899: =O2899-N2899+1 -> 365 | Z2899: =$Z$1 -> 46081 | AA2899: =IF(MIN((Z2899-N2899)+1,Y2899)<0,0,MIN((Z2899-N2899)+1,Y2899)) -> 181 | AB2899: Maharashtra | AC2899: =AE2899+AF2899+AG2899+AH2899 -> 11909.728 | AD2899: 1 | AE2899: =INDEX(SA!$C$2:$G$11,MATCH(Details!S2899,SA!$C$2:$C$11,0),MATCH(Details!V2899,SA!$C$2:$G$2,0))*Y2899/(F2899-E2899+1) -> 10092.99 | AF2899: =IF(AB2899="Karnataka",AE2899*9%,0) -> 0 | AG2899: =IF(AB2899="Karnataka",AE2899*9%,0) -> 0 | AH2899: =IF(AF2899+AG2899>0,0,AE2899*18%) -> 1816.7382 | AI2899: =AE2899*L2899 -> 403.7196 | AJ2899: =$AE2899*M2899 -> 2270.9228 | AK2899: =(AE2899)*AA2899/Y2899 -> 5005.017 | AL2899: =AK2899*(1-L2899-M2899) -> 3678.6875 | AM2899: =AE2899-AI2899-AL2899-AJ2899 -> 3739.6602 | AN2899: =Z2899-366 -> 45715 | AO2899: =IF(AND(O2899>Z2899,N2899>AN2899),AE2899,0) -> 10092.99
A2900: Valid | B2900: 202509 | C2900: GMC023220100CALDERYS | D2900: CALDERYS INDIA REFRACTORIES LIMITED | E2900: 45901 | F2900: 46265 | G2900: Rupesh Singh | H2900: 45029 | I2900: 36435 | J2900: ACK.4A9F3020250709.3 | K2900: =N2900 -> 45901 | L2900: =IF(K2900>=DATE(2022,4,1),4%,5%) -> 0.04 | M2900: 0.225 | N2900: 45901 | O2900: 46265 | R2900: 25 | S2900: =VLOOKUP(R2900,SA!$B$3:$C$11,2,1) -> 0-25 | T2900: Male | U2900: Self | V2900: 400000 | W2900: =IF(U2900="self",V2900,0) -> 400000 | X2900: =IF(U2900="self",1,0) -> 1 | Y2900: =O2900-N2900+1 -> 365 | Z2900: =$Z$1 -> 46081 | AA2900: =IF(MIN((Z2900-N2900)+1,Y2900)<0,0,MIN((Z2900-N2900)+1,Y2900)) -> 181 | AB2900: Maharashtra | AC2900: =AE2900+AF2900+AG2900+AH2900 -> 4043.8364 | AD2900: 1 | AE2900: =INDEX(SA!$C$2:$G$11,MATCH(Details!S2900,SA!$C$2:$C$11,0),MATCH(Details!V2900,SA!$C$2:$G$2,0))*Y2900/(F2900-E2900+1) -> 3426.98 | AF2900: =IF(AB2900="Karnataka",AE2900*9%,0) -> 0 | AG2900: =IF(AB2900="Karnataka",AE2900*9%,0) -> 0 | AH2900: =IF(AF2900+AG2900>0,0,AE2900*18%) -> 616.8564 | AI2900: =AE2900*L2900 -> 137.0792 | AJ2900: =$AE2900*M2900 -> 771.0705 | AK2900: =(AE2900)*AA2900/Y2900 -> 1699.4065 | AL2900: =AK2900*(1-L2900-M2900) -> 1249.0638 | AM2900: =AE2900-AI2900-AL2900-AJ2900 -> 1269.7665 | AN2900: =Z2900-366 -> 45715 | AO2900: =IF(AND(O2900>Z2900,N2900>AN2900),AE2900,0) -> 3426.98
A2901: Valid | B2901: 202509 | C2901: GMC023220100CALDERYS | D2901: CALDERYS INDIA REFRACTORIES LIMITED | E2901: 45901 | F2901: 46265 | G2901: Nitu Kumari | H2901: 652602 | I2901: 36319 | J2901: ACK.4A9F3020250714.1 | K2901: =N2901 -> 45901 | L2901: =IF(K2901>=DATE(2022,4,1),4%,5%) -> 0.04 | M2901: 0.225 | N2901: 45901 | O2901: 46265 | R2901: 26 | S2901: =VLOOKUP(R2901,SA!$B$3:$C$11,2,1) -> 26-35 | T2901: Female | U2901: Self | V2901: 400000 | W2901: =IF(U2901="self",V2901,0) -> 400000 | X2901: =IF(U2901="self",1,0) -> 1 | Y2901: =O2901-N2901+1 -> 365 | Z2901: =$Z$1 -> 46081 | AA2901: =IF(MIN((Z2901-N2901)+1,Y2901)<0,0,MIN((Z2901-N2901)+1,Y2901)) -> 181 | AB2901: Maharashtra | AC2901: =AE2901+AF2901+AG2901+AH2901 -> 4533.029 | AD2901: 1 | AE2901: =INDEX(SA!$C$2:$G$11,MATCH(Details!S2901,SA!$C$2:$C$11,0),MATCH(Details!V2901,SA!$C$2:$G$2,0))*Y2901/(F2901-E2901+1) -> 3841.55 | AF2901: =IF(AB2901="Karnataka",AE2901*9%,0) -> 0 | AG2901: =IF(AB2901="Karnataka",AE2901*9%,0) -> 0 | AH2901: =IF(AF2901+AG2901>0,0,AE2901*18%) -> 691.479 | AI2901: =AE2901*L2901 -> 153.662 | AJ2901: =$AE2901*M2901 -> 864.34875 | AK2901: =(AE2901)*AA2901/Y2901 -> 1904.9878 | AL2901: =AK2901*(1-L2901-M2901) -> 1400.166 | AM2901: =AE2901-AI2901-AL2901-AJ2901 -> 1423.3732 | AN2901: =Z2901-366 -> 45715 | AO2901: =IF(AND(O2901>Z2901,N2901>AN2901),AE2901,0) -> 3841.55
A2902: Valid | B2902: 202509 | C2902: GMC023220100CALDERYS | D2902: CALDERYS INDIA REFRACTORIES LIMITED | E2902: 45901 | F2902: 46265 | G2902: Umesh Ram | H2902: 652602 | I2902: 25934 | J2902: ACK.4A9F3020250714.2 | K2902: =N2902 -> 45901 | L2902: =IF(K2902>=DATE(2022,4,1),4%,5%) -> 0.04 | M2902: 0.225 | N2902: 45901 | O2902: 46265 | R2902: 54 | S2902: =VLOOKUP(R2902,SA!$B$3:$C$11,2,1) -> 46-55 | T2902: Male | U2902: Father | V2902: 400000 | W2902: =IF(U2902="self",V2902,0) -> 0 | X2902: =IF(U2902="self",1,0) -> 0 | Y2902: =O2902-N2902+1 -> 365 | Z2902: =$Z$1 -> 46081 | AA2902: =IF(MIN((Z2902-N2902)+1,Y2902)<0,0,MIN((Z2902-N2902)+1,Y2902)) -> 181 | AB2902: Maharashtra | AC2902: =AE2902+AF2902+AG2902+AH2902 -> 8108.2166 | AD2902: 1 | AE2902: =INDEX(SA!$C$2:$G$11,MATCH(Details!S2902,SA!$C$2:$C$11,0),MATCH(Details!V2902,SA!$C$2:$G$2,0))*Y2902/(F2902-E2902+1) -> 6871.37 | AF2902: =IF(AB2902="Karnataka",AE2902*9%,0) -> 0 | AG2902: =IF(AB2902="Karnataka",AE2902*9%,0) -> 0 | AH2902: =IF(AF2902+AG2902>0,0,AE2902*18%) -> 1236.8466 | AI2902: =AE2902*L2902 -> 274.8548 | AJ2902: =$AE2902*M2902 -> 1546.0583 | AK2902: =(AE2902)*AA2902/Y2902 -> 3407.4465 | AL2902: =AK2902*(1-L2902-M2902) -> 2504.4732 | AM2902: =AE2902-AI2902-AL2902-AJ2902 -> 2545.9838 | AN2902: =Z2902-366 -> 45715 | AO2902: =IF(AND(O2902>Z2902,N2902>AN2902),AE2902,0) -> 6871.37
